2025-04-18 13:05:47,422 - INFO - Successfully imported Trainer, TrainerArgs, load_tts_samples, setup_model from TTS.bin.train_tts
2025-04-18 13:05:52,490 - INFO - Found config for Hu Tao: voice_datasets\Hu Tao\Hu Tao_config.json
2025-04-18 13:05:52,491 - INFO - Found config for Xiao: voice_datasets\Xiao\Xiao_config.json
2025-04-18 13:05:52,491 - INFO - Found 2 character configs in voice_datasets
2025-04-18 13:32:44,235 - INFO - Successfully imported Trainer, TrainerArgs, load_tts_samples, setup_model from TTS.bin.train_tts
2025-04-18 13:32:49,206 - INFO - Found config for Hu Tao: voice_datasets\Hu Tao\Hu Tao_config.json
2025-04-18 13:32:49,207 - INFO - Found config for Xiao: voice_datasets\Xiao\Xiao_config.json
2025-04-18 13:32:49,208 - INFO - Found 2 character configs in voice_datasets
2025-04-18 13:33:03,295 - INFO - Loaded configuration from voice_datasets\Hu Tao\Hu Tao_config.json
2025-04-18 13:33:03,298 - INFO - Loaded configuration from voice_datasets\Hu Tao\Hu Tao_config.json
2025-04-18 13:33:03,298 - INFO - Model tts_models/en/ek1/tacotron2 not found in cache. Attempting to download.
2025-04-18 13:33:03,310 - INFO - Successfully downloaded model: tts_models/en/ek1/tacotron2 to C:\Users\DRAGOHN/.cache/tts/tts_models--en--ek1--tacotron2
2025-04-18 13:33:03,310 - INFO - Using CPU for training.
2025-04-18 13:33:03,311 - INFO - Checking training metadata file at: voice_datasets\Hu Tao\wavs\metadata.csv
2025-04-18 13:33:03,311 - INFO - Checking validation metadata file at: voice_datasets\Hu Tao\wavs\valid.csv
2025-04-18 13:33:03,312 - ERROR - Training failed: Training metadata file not found: voice_datasets\Hu Tao\wavs\metadata.csv
Traceback (most recent call last):
  File "D:\Scripts\EchoPersona\train_tts_model.py", line 253, in train_model
    raise FileNotFoundError(
FileNotFoundError: Training metadata file not found: voice_datasets\Hu Tao\wavs\metadata.csv

2025-04-18 13:34:53,659 - INFO - Successfully imported Trainer, TrainerArgs, load_tts_samples, setup_model from TTS.bin.train_tts
2025-04-18 13:34:59,175 - INFO - Found config for Hu Tao: voice_datasets\Hu Tao\Hu Tao_config.json
2025-04-18 13:34:59,177 - INFO - Found config for Xiao: voice_datasets\Xiao\Xiao_config.json
2025-04-18 13:34:59,178 - INFO - Found 2 character configs in voice_datasets
2025-04-18 13:35:03,536 - INFO - Loaded configuration from voice_datasets\Hu Tao\Hu Tao_config.json
2025-04-18 13:35:03,539 - INFO - Loaded configuration from voice_datasets\Hu Tao\Hu Tao_config.json
2025-04-18 13:35:03,539 - INFO - Model tts_models/en/ek1/tacotron2 not found in cache. Attempting to download.
2025-04-18 13:35:03,553 - INFO - Successfully downloaded model: tts_models/en/ek1/tacotron2 to C:\Users\DRAGOHN/.cache/tts/tts_models--en--ek1--tacotron2
2025-04-18 13:35:03,553 - INFO - Using CPU for training.
2025-04-18 13:35:03,554 - INFO - Checking training metadata file at: D:\Scripts\EchoPersona\voice_datasets\Hu Tao\wavs\metadata.csv
2025-04-18 13:35:03,555 - INFO - Checking validation metadata file at: D:\Scripts\EchoPersona\voice_datasets\Hu Tao\wavs\valid.csv
2025-04-18 13:35:03,555 - ERROR - Training failed: Training metadata file not found: D:\Scripts\EchoPersona\voice_datasets\Hu Tao\wavs\metadata.csv
Traceback (most recent call last):
  File "D:\Scripts\EchoPersona\train_tts_model.py", line 254, in train_model
    raise FileNotFoundError(
FileNotFoundError: Training metadata file not found: D:\Scripts\EchoPersona\voice_datasets\Hu Tao\wavs\metadata.csv

2025-04-18 13:36:56,910 - INFO - Successfully imported Trainer, TrainerArgs, load_tts_samples, setup_model from TTS.bin.train_tts
2025-04-18 13:37:01,917 - INFO - Found config for Hu Tao: voice_datasets\Hu Tao\Hu Tao_config.json
2025-04-18 13:37:01,918 - INFO - Found config for Xiao: voice_datasets\Xiao\Xiao_config.json
2025-04-18 13:37:01,918 - INFO - Found 2 character configs in voice_datasets
2025-04-18 13:37:35,255 - INFO - Loaded configuration from voice_datasets\Hu Tao\Hu Tao_config.json
2025-04-18 13:37:35,260 - INFO - Loaded configuration from voice_datasets\Hu Tao\Hu Tao_config.json
2025-04-18 13:37:35,261 - INFO - Model tts_models/en/ek1/tacotron2 not found in cache. Attempting to download.
2025-04-18 13:37:35,274 - INFO - Successfully downloaded model: tts_models/en/ek1/tacotron2 to C:\Users\DRAGOHN/.cache/tts/tts_models--en--ek1--tacotron2
2025-04-18 13:37:35,274 - INFO - Using CPU for training.
2025-04-18 13:37:35,276 - INFO - Checking training metadata file at: D:\Scripts\EchoPersona\voice_datasets\Hu Tao\wavs\metadata.csv
2025-04-18 13:37:35,277 - INFO - Checking validation metadata file at: D:\Scripts\EchoPersona\voice_datasets\Hu Tao\wavs\valid.csv
2025-04-18 13:37:35,277 - ERROR - Training failed: Training metadata file not found: D:\Scripts\EchoPersona\voice_datasets\Hu Tao\wavs\metadata.csv
Traceback (most recent call last):
  File "D:\Scripts\EchoPersona\train_tts_model.py", line 254, in train_model
    raise FileNotFoundError(
FileNotFoundError: Training metadata file not found: D:\Scripts\EchoPersona\voice_datasets\Hu Tao\wavs\metadata.csv

2025-04-18 13:54:45,814 - INFO - Successfully imported Trainer, TrainerArgs, load_tts_samples, setup_model from TTS.bin.train_tts
2025-04-18 13:54:50,866 - INFO - Found config for Zhongli: voice_datasets\Zhongli\Zhongli_config.json
2025-04-18 13:54:50,866 - INFO - Found 1 character configs in voice_datasets
2025-04-18 13:54:57,666 - INFO - Loaded configuration from voice_datasets\Zhongli\Zhongli_config.json
2025-04-18 13:54:57,670 - INFO - Loaded configuration from voice_datasets\Zhongli\Zhongli_config.json
2025-04-18 13:54:57,670 - INFO - Model tts_models/en/ek1/tacotron2 not found in cache. Attempting to download.
2025-04-18 13:54:57,682 - INFO - Successfully downloaded model: tts_models/en/ek1/tacotron2 to C:\Users\DRAGOHN/.cache/tts/tts_models--en--ek1--tacotron2
2025-04-18 13:54:57,683 - INFO - Using CPU for training.
2025-04-18 13:54:57,684 - INFO - Checking training metadata file at: D:\Scripts\EchoPersona\voice_datasets\Zhongli\wavs\metadata.csv
2025-04-18 13:54:57,684 - INFO - Checking validation metadata file at: D:\Scripts\EchoPersona\voice_datasets\Zhongli\wavs\valid.csv
2025-04-18 13:54:57,686 - ERROR - Training failed: Training metadata file not found: D:\Scripts\EchoPersona\voice_datasets\Zhongli\wavs\metadata.csv
Traceback (most recent call last):
  File "D:\Scripts\EchoPersona\train_tts_model.py", line 254, in train_model
    raise FileNotFoundError(
FileNotFoundError: Training metadata file not found: D:\Scripts\EchoPersona\voice_datasets\Zhongli\wavs\metadata.csv

2025-04-18 13:55:10,084 - INFO - Loaded configuration from voice_datasets\Zhongli\Zhongli_config.json
2025-04-18 13:55:10,084 - ERROR - Required path does not exist: voice_datasets\Zhongli\metadata.csv
2025-04-18 13:55:10,084 - ERROR - Failed to load configuration from voice_datasets\Zhongli\Zhongli_config.json: Invalid configuration: Missing or non-existent data paths.
2025-04-18 13:55:56,585 - INFO - Successfully imported Trainer, TrainerArgs, load_tts_samples, setup_model from TTS.bin.train_tts
2025-04-18 13:56:01,543 - INFO - Found config for Zhongli: voice_datasets\Zhongli\Zhongli_config.json
2025-04-18 13:56:01,543 - INFO - Found 1 character configs in voice_datasets
2025-04-18 13:56:08,065 - INFO - Loaded configuration from voice_datasets\Zhongli\Zhongli_config.json
2025-04-18 13:56:08,067 - INFO - Loaded configuration from voice_datasets\Zhongli\Zhongli_config.json
2025-04-18 13:56:08,068 - INFO - Model tts_models/en/ek1/tacotron2 not found in cache. Attempting to download.
2025-04-18 13:56:08,079 - INFO - Successfully downloaded model: tts_models/en/ek1/tacotron2 to C:\Users\DRAGOHN/.cache/tts/tts_models--en--ek1--tacotron2
2025-04-18 13:56:08,080 - INFO - Using CPU for training.
2025-04-18 13:56:08,081 - INFO - Checking training metadata file at: D:\Scripts\EchoPersona\voice_datasets\Zhongli\wavs\metadata.csv
2025-04-18 13:56:08,081 - INFO - Checking validation metadata file at: D:\Scripts\EchoPersona\voice_datasets\Zhongli\wavs\valid.csv
2025-04-18 13:56:08,081 - ERROR - Training failed: Validation metadata file not found: D:\Scripts\EchoPersona\voice_datasets\Zhongli\wavs\valid.csv
Traceback (most recent call last):
  File "D:\Scripts\EchoPersona\train_tts_model.py", line 258, in train_model
    raise FileNotFoundError(
FileNotFoundError: Validation metadata file not found: D:\Scripts\EchoPersona\voice_datasets\Zhongli\wavs\valid.csv

2025-04-18 13:56:25,477 - INFO - Loaded configuration from voice_datasets\Zhongli\Zhongli_config.json
2025-04-18 13:56:25,479 - INFO - Loaded configuration from voice_datasets\Zhongli\Zhongli_config.json
2025-04-18 13:56:25,480 - INFO - Model tts_models/en/ek1/tacotron2 not found in cache. Attempting to download.
2025-04-18 13:56:25,487 - INFO - Successfully downloaded model: tts_models/en/ek1/tacotron2 to C:\Users\DRAGOHN/.cache/tts/tts_models--en--ek1--tacotron2
2025-04-18 13:56:25,487 - INFO - Using CPU for training.
2025-04-18 13:56:25,488 - INFO - Checking training metadata file at: D:\Scripts\EchoPersona\voice_datasets\Zhongli\wavs\metadata.csv
2025-04-18 13:56:25,488 - INFO - Checking validation metadata file at: D:\Scripts\EchoPersona\voice_datasets\Zhongli\wavs\valid.csv
2025-04-18 13:56:25,489 - INFO - Using Trainer.fit with dataset preprocessing from TTS.bin.train_tts
2025-04-18 13:56:25,491 - WARNING - Trainer.fit with preprocessing failed: 'dict' object has no attribute 'meta_file_attn_mask'
Traceback (most recent call last):
  File "D:\Scripts\EchoPersona\train_tts_model.py", line 269, in train_model
    train_samples, eval_samples = load_tts_samples(
                                  ^^^^^^^^^^^^^^^^^
  File "D:\Scripts\EchoPersona\.venv\Lib\site-packages\TTS\tts\datasets\__init__.py", line 137, in load_tts_samples
    if dataset.meta_file_attn_mask:
       ^^^^^^^^^^^^^^^^^^^^^^^^^^^
AttributeError: 'dict' object has no attribute 'meta_file_attn_mask'

2025-04-18 13:56:25,491 - INFO - Attempting manual dataset handling with Trainer.fit
2025-04-18 13:56:25,493 - INFO - Loaded configuration from voice_datasets\Zhongli\Zhongli_config.json
2025-04-18 13:56:25,496 - ERROR - Manual dataset handling failed: 'dict' object has no attribute 'parse_known_args'
Traceback (most recent call last):
  File "D:\Scripts\EchoPersona\train_tts_model.py", line 269, in train_model
    train_samples, eval_samples = load_tts_samples(
                                  ^^^^^^^^^^^^^^^^^
  File "D:\Scripts\EchoPersona\.venv\Lib\site-packages\TTS\tts\datasets\__init__.py", line 137, in load_tts_samples
    if dataset.meta_file_attn_mask:
       ^^^^^^^^^^^^^^^^^^^^^^^^^^^
AttributeError: 'dict' object has no attribute 'meta_file_attn_mask'

During handling of the above exception, another exception occurred:

Traceback (most recent call last):
  File "D:\Scripts\EchoPersona\train_tts_model.py", line 324, in train_model
    trainer = Trainer(
              ^^^^^^^^
  File "D:\Scripts\EchoPersona\.venv\Lib\site-packages\trainer\trainer.py", line 400, in __init__
    config, new_fields = self.init_training(args, coqpit_overrides, config)
                         ^^^^^^^^^^^^^^^^^^^^^^^^^^^^^^^^^^^^^^^^^^^^^^^^^^
  File "D:\Scripts\EchoPersona\.venv\Lib\site-packages\trainer\trainer.py", line 745, in init_training
    config.parse_known_args(coqpit_overrides, relaxed_parser=True)
    ^^^^^^^^^^^^^^^^^^^^^^^
AttributeError: 'dict' object has no attribute 'parse_known_args'

2025-04-18 13:56:25,499 - ERROR - Training failed: All Trainer.fit attempts failed
Traceback (most recent call last):
  File "D:\Scripts\EchoPersona\train_tts_model.py", line 269, in train_model
    train_samples, eval_samples = load_tts_samples(
                                  ^^^^^^^^^^^^^^^^^
  File "D:\Scripts\EchoPersona\.venv\Lib\site-packages\TTS\tts\datasets\__init__.py", line 137, in load_tts_samples
    if dataset.meta_file_attn_mask:
       ^^^^^^^^^^^^^^^^^^^^^^^^^^^
AttributeError: 'dict' object has no attribute 'meta_file_attn_mask'

During handling of the above exception, another exception occurred:

Traceback (most recent call last):
  File "D:\Scripts\EchoPersona\train_tts_model.py", line 324, in train_model
    trainer = Trainer(
              ^^^^^^^^
  File "D:\Scripts\EchoPersona\.venv\Lib\site-packages\trainer\trainer.py", line 400, in __init__
    config, new_fields = self.init_training(args, coqpit_overrides, config)
                         ^^^^^^^^^^^^^^^^^^^^^^^^^^^^^^^^^^^^^^^^^^^^^^^^^^
  File "D:\Scripts\EchoPersona\.venv\Lib\site-packages\trainer\trainer.py", line 745, in init_training
    config.parse_known_args(coqpit_overrides, relaxed_parser=True)
    ^^^^^^^^^^^^^^^^^^^^^^^
AttributeError: 'dict' object has no attribute 'parse_known_args'

During handling of the above exception, another exception occurred:

Traceback (most recent call last):
  File "D:\Scripts\EchoPersona\train_tts_model.py", line 343, in train_model
    raise RuntimeError("All Trainer.fit attempts failed")
RuntimeError: All Trainer.fit attempts failed

2025-04-18 14:35:37,237 - INFO - Successfully imported Trainer, TrainerArgs, load_tts_samples, setup_model from TTS.bin.train_tts
2025-04-18 14:35:42,315 - INFO - Found config for Zhongli: voice_datasets\Zhongli\zhongli_config.json
2025-04-18 14:35:42,316 - INFO - Found 1 character configs in voice_datasets
2025-04-18 14:35:51,907 - INFO - Loaded configuration from voice_datasets\Zhongli\zhongli_config.json
2025-04-18 14:35:51,908 - INFO - Loaded configuration from voice_datasets\Zhongli\zhongli_config.json
2025-04-18 14:35:51,910 - INFO - Model tts_models/en/ek1/tacotron2 not found in cache. Attempting to download.
2025-04-18 14:35:51,921 - INFO - Successfully downloaded model: tts_models/en/ek1/tacotron2 to C:\Users\DRAGOHN/.cache/tts/tts_models--en--ek1--tacotron2
2025-04-18 14:35:51,922 - INFO - Using CPU for training.
2025-04-18 14:35:51,924 - INFO - Using training metadata file at: voice_datasets\Zhongli\metadata.csv
2025-04-18 14:35:51,924 - INFO - Using validation metadata file at: voice_datasets\Zhongli\valid.csv
2025-04-18 14:35:51,924 - INFO - Using Trainer.fit with dataset preprocessing from TTS.bin.train_tts
2025-04-18 14:35:51,925 - WARNING - Trainer.fit with preprocessing failed: [Errno 2] No such file or directory: 'voice_datasets\\Zhongli\\wavs\\metadata.csv'
Traceback (most recent call last):
  File "D:\Scripts\EchoPersona\train_tts_model.py", line 280, in train_model
    train_samples, eval_samples = load_tts_samples(
                                  ^^^^^^^^^^^^^^^^^
  File "D:\Scripts\EchoPersona\.venv\Lib\site-packages\TTS\tts\datasets\__init__.py", line 120, in load_tts_samples
    meta_data_train = formatter(root_path, meta_file_train, ignored_speakers=ignored_speakers)
                      ^^^^^^^^^^^^^^^^^^^^^^^^^^^^^^^^^^^^^^^^^^^^^^^^^^^^^^^^^^^^^^^^^^^^^^^^
  File "D:\Scripts\EchoPersona\.venv\Lib\site-packages\TTS\tts\datasets\formatters.py", line 197, in ljspeech
    with open(txt_file, "r", encoding="utf-8") as ttf:
         ^^^^^^^^^^^^^^^^^^^^^^^^^^^^^^^^^^^^^
FileNotFoundError: [Errno 2] No such file or directory: 'voice_datasets\\Zhongli\\wavs\\metadata.csv'

2025-04-18 14:35:51,926 - INFO - Attempting manual dataset handling with Trainer.fit
2025-04-18 14:35:51,926 - INFO - Loaded configuration from voice_datasets\Zhongli\zhongli_config.json
2025-04-18 14:35:51,930 - ERROR - Manual dataset handling failed: 'dict' object has no attribute 'parse_known_args'
Traceback (most recent call last):
  File "D:\Scripts\EchoPersona\train_tts_model.py", line 280, in train_model
    train_samples, eval_samples = load_tts_samples(
                                  ^^^^^^^^^^^^^^^^^
  File "D:\Scripts\EchoPersona\.venv\Lib\site-packages\TTS\tts\datasets\__init__.py", line 120, in load_tts_samples
    meta_data_train = formatter(root_path, meta_file_train, ignored_speakers=ignored_speakers)
                      ^^^^^^^^^^^^^^^^^^^^^^^^^^^^^^^^^^^^^^^^^^^^^^^^^^^^^^^^^^^^^^^^^^^^^^^^
  File "D:\Scripts\EchoPersona\.venv\Lib\site-packages\TTS\tts\datasets\formatters.py", line 197, in ljspeech
    with open(txt_file, "r", encoding="utf-8") as ttf:
         ^^^^^^^^^^^^^^^^^^^^^^^^^^^^^^^^^^^^^
FileNotFoundError: [Errno 2] No such file or directory: 'voice_datasets\\Zhongli\\wavs\\metadata.csv'

During handling of the above exception, another exception occurred:

Traceback (most recent call last):
  File "D:\Scripts\EchoPersona\train_tts_model.py", line 335, in train_model
    trainer = Trainer(
              ^^^^^^^^
  File "D:\Scripts\EchoPersona\.venv\Lib\site-packages\trainer\trainer.py", line 400, in __init__
    config, new_fields = self.init_training(args, coqpit_overrides, config)
                         ^^^^^^^^^^^^^^^^^^^^^^^^^^^^^^^^^^^^^^^^^^^^^^^^^^
  File "D:\Scripts\EchoPersona\.venv\Lib\site-packages\trainer\trainer.py", line 745, in init_training
    config.parse_known_args(coqpit_overrides, relaxed_parser=True)
    ^^^^^^^^^^^^^^^^^^^^^^^
AttributeError: 'dict' object has no attribute 'parse_known_args'

2025-04-18 14:35:51,933 - ERROR - Training failed: All Trainer.fit attempts failed
Traceback (most recent call last):
  File "D:\Scripts\EchoPersona\train_tts_model.py", line 280, in train_model
    train_samples, eval_samples = load_tts_samples(
                                  ^^^^^^^^^^^^^^^^^
  File "D:\Scripts\EchoPersona\.venv\Lib\site-packages\TTS\tts\datasets\__init__.py", line 120, in load_tts_samples
    meta_data_train = formatter(root_path, meta_file_train, ignored_speakers=ignored_speakers)
                      ^^^^^^^^^^^^^^^^^^^^^^^^^^^^^^^^^^^^^^^^^^^^^^^^^^^^^^^^^^^^^^^^^^^^^^^^
  File "D:\Scripts\EchoPersona\.venv\Lib\site-packages\TTS\tts\datasets\formatters.py", line 197, in ljspeech
    with open(txt_file, "r", encoding="utf-8") as ttf:
         ^^^^^^^^^^^^^^^^^^^^^^^^^^^^^^^^^^^^^
FileNotFoundError: [Errno 2] No such file or directory: 'voice_datasets\\Zhongli\\wavs\\metadata.csv'

During handling of the above exception, another exception occurred:

Traceback (most recent call last):
  File "D:\Scripts\EchoPersona\train_tts_model.py", line 335, in train_model
    trainer = Trainer(
              ^^^^^^^^
  File "D:\Scripts\EchoPersona\.venv\Lib\site-packages\trainer\trainer.py", line 400, in __init__
    config, new_fields = self.init_training(args, coqpit_overrides, config)
                         ^^^^^^^^^^^^^^^^^^^^^^^^^^^^^^^^^^^^^^^^^^^^^^^^^^
  File "D:\Scripts\EchoPersona\.venv\Lib\site-packages\trainer\trainer.py", line 745, in init_training
    config.parse_known_args(coqpit_overrides, relaxed_parser=True)
    ^^^^^^^^^^^^^^^^^^^^^^^
AttributeError: 'dict' object has no attribute 'parse_known_args'

During handling of the above exception, another exception occurred:

Traceback (most recent call last):
  File "D:\Scripts\EchoPersona\train_tts_model.py", line 354, in train_model
    raise RuntimeError("All Trainer.fit attempts failed")
RuntimeError: All Trainer.fit attempts failed

2025-04-18 14:44:07,508 - INFO - Successfully imported Trainer, TrainerArgs, load_tts_samples, setup_model from TTS.bin.train_tts
2025-04-18 14:44:13,235 - INFO - Found config for Zhongli: voice_datasets\Zhongli\zhongli_config.json
2025-04-18 14:44:13,235 - INFO - Found 1 character configs in voice_datasets
2025-04-18 14:44:19,153 - INFO - Loaded configuration from voice_datasets\Zhongli\zhongli_config.json
2025-04-18 14:44:19,155 - INFO - Loaded configuration from voice_datasets\Zhongli\zhongli_config.json
2025-04-18 14:44:19,156 - INFO - Model tts_models/en/ek1/tacotron2 not found in cache. Attempting to download.
2025-04-18 14:44:19,168 - INFO - Successfully downloaded model: tts_models/en/ek1/tacotron2 to C:\Users\DRAGOHN/.cache/tts/tts_models--en--ek1--tacotron2
2025-04-18 14:44:19,169 - INFO - Using CPU for training.
2025-04-18 14:44:19,170 - ERROR - Training failed: Metadata files not found in expected locations: voice_datasets\Zhongli\voice_datasets\Zhongli\metadata.csv, voice_datasets\Zhongli\voice_datasets\Zhongli\valid.csv
Traceback (most recent call last):
  File "D:\Scripts\EchoPersona\train_tts_model.py", line 271, in train_model
    meta_file_train_path, meta_file_val_path = adjust_metadata_paths(dataset_path, meta_file_train, meta_file_val)
                                               ^^^^^^^^^^^^^^^^^^^^^^^^^^^^^^^^^^^^^^^^^^^^^^^^^^^^^^^^^^^^^^^^^^^
  File "D:\Scripts\EchoPersona\train_tts_model.py", line 214, in adjust_metadata_paths
    raise FileNotFoundError(
FileNotFoundError: Metadata files not found in expected locations: voice_datasets\Zhongli\voice_datasets\Zhongli\metadata.csv, voice_datasets\Zhongli\voice_datasets\Zhongli\valid.csv

2025-04-18 14:46:08,734 - INFO - Successfully imported Trainer, TrainerArgs, load_tts_samples, setup_model from TTS.bin.train_tts
2025-04-18 14:46:13,674 - INFO - Found config for Zhongli: voice_datasets\Zhongli\zhongli_config.json
2025-04-18 14:46:13,674 - INFO - Found 1 character configs in voice_datasets
2025-04-18 14:46:21,304 - INFO - Loaded configuration from voice_datasets\Zhongli\zhongli_config.json
2025-04-18 14:46:21,305 - INFO - Loaded configuration from voice_datasets\Zhongli\zhongli_config.json
2025-04-18 14:46:21,306 - INFO - Model tts_models/en/ek1/tacotron2 not found in cache. Attempting to download.
2025-04-18 14:46:21,319 - INFO - Successfully downloaded model: tts_models/en/ek1/tacotron2 to C:\Users\DRAGOHN/.cache/tts/tts_models--en--ek1--tacotron2
2025-04-18 14:46:21,320 - INFO - Using CPU for training.
2025-04-18 14:46:21,321 - INFO - Using training metadata file at: voice_datasets\Zhongli\metadata.csv
2025-04-18 14:46:21,322 - INFO - Using validation metadata file at: voice_datasets\Zhongli\valid.csv
2025-04-18 14:46:21,322 - ERROR - Training failed: Coqpit.__init__() got an unexpected keyword argument 'output_path'
Traceback (most recent call last):
  File "D:\Scripts\EchoPersona\train_tts_model.py", line 282, in train_model
    config = Coqpit(**config)
             ^^^^^^^^^^^^^^^^
TypeError: Coqpit.__init__() got an unexpected keyword argument 'output_path'

2025-04-18 14:47:24,730 - INFO - Successfully imported Trainer, TrainerArgs, load_tts_samples, setup_model from TTS.bin.train_tts
2025-04-18 14:47:29,778 - INFO - Found config for Zhongli: voice_datasets\Zhongli\zhongli_config.json
2025-04-18 14:47:29,778 - INFO - Found 1 character configs in voice_datasets
2025-04-18 14:47:35,488 - INFO - Loaded configuration from voice_datasets\Zhongli\zhongli_config.json
2025-04-18 14:47:35,492 - INFO - Loaded configuration from voice_datasets\Zhongli\zhongli_config.json
2025-04-18 14:47:35,493 - INFO - Model tts_models/en/ek1/tacotron2 not found in cache. Attempting to download.
2025-04-18 14:47:35,505 - INFO - Successfully downloaded model: tts_models/en/ek1/tacotron2 to C:\Users\DRAGOHN/.cache/tts/tts_models--en--ek1--tacotron2
2025-04-18 14:47:35,505 - INFO - Using CPU for training.
2025-04-18 14:47:35,507 - INFO - Using training metadata file at: voice_datasets\Zhongli\metadata.csv
2025-04-18 14:47:35,507 - INFO - Using validation metadata file at: voice_datasets\Zhongli\valid.csv
2025-04-18 14:47:35,508 - ERROR - Training failed: Coqpit.__init__() got an unexpected keyword argument 'datasets'
Traceback (most recent call last):
  File "D:\Scripts\EchoPersona\train_tts_model.py", line 284, in train_model
    config = Coqpit(**filtered_config)
             ^^^^^^^^^^^^^^^^^^^^^^^^^
TypeError: Coqpit.__init__() got an unexpected keyword argument 'datasets'

2025-04-18 14:49:05,634 - INFO - Successfully imported Trainer, TrainerArgs, load_tts_samples, setup_model from TTS.bin.train_tts
2025-04-18 14:49:10,678 - INFO - Found config for Zhongli: voice_datasets\Zhongli\zhongli_config.json
2025-04-18 14:49:10,678 - INFO - Found 1 character configs in voice_datasets
2025-04-18 14:49:18,716 - INFO - Loaded configuration from voice_datasets\Zhongli\zhongli_config.json
2025-04-18 14:49:18,720 - INFO - Loaded configuration from voice_datasets\Zhongli\zhongli_config.json
2025-04-18 14:49:18,721 - INFO - Model tts_models/en/ek1/tacotron2 not found in cache. Attempting to download.
2025-04-18 14:49:18,734 - INFO - Successfully downloaded model: tts_models/en/ek1/tacotron2 to C:\Users\DRAGOHN/.cache/tts/tts_models--en--ek1--tacotron2
2025-04-18 14:49:18,735 - INFO - Using CPU for training.
2025-04-18 14:49:18,736 - INFO - Using training metadata file at: voice_datasets\Zhongli\metadata.csv
2025-04-18 14:49:18,736 - INFO - Using validation metadata file at: voice_datasets\Zhongli\valid.csv
2025-04-18 14:49:18,738 - ERROR - Training failed: Coqpit.__init__() got an unexpected keyword argument 'audio'
Traceback (most recent call last):
  File "D:\Scripts\EchoPersona\train_tts_model.py", line 284, in train_model
    config = Coqpit(**filtered_config)
             ^^^^^^^^^^^^^^^^^^^^^^^^^
TypeError: Coqpit.__init__() got an unexpected keyword argument 'audio'

2025-04-18 14:50:11,568 - INFO - Successfully imported Trainer, TrainerArgs, load_tts_samples, setup_model from TTS.bin.train_tts
2025-04-18 14:50:16,669 - INFO - Found config for Zhongli: voice_datasets\Zhongli\zhongli_config.json
2025-04-18 14:50:16,669 - INFO - Found 1 character configs in voice_datasets
2025-04-18 14:50:22,630 - INFO - Loaded configuration from voice_datasets\Zhongli\zhongli_config.json
2025-04-18 14:50:22,633 - INFO - Loaded configuration from voice_datasets\Zhongli\zhongli_config.json
2025-04-18 14:50:22,633 - INFO - Model tts_models/en/ek1/tacotron2 not found in cache. Attempting to download.
2025-04-18 14:50:22,646 - INFO - Successfully downloaded model: tts_models/en/ek1/tacotron2 to C:\Users\DRAGOHN/.cache/tts/tts_models--en--ek1--tacotron2
2025-04-18 14:50:22,647 - INFO - Using CPU for training.
2025-04-18 14:50:22,648 - INFO - Using training metadata file at: voice_datasets\Zhongli\metadata.csv
2025-04-18 14:50:22,648 - INFO - Using validation metadata file at: voice_datasets\Zhongli\valid.csv
2025-04-18 14:50:22,649 - ERROR - Training failed: Coqpit.__init__() got an unexpected keyword argument 'model'
Traceback (most recent call last):
  File "D:\Scripts\EchoPersona\train_tts_model.py", line 284, in train_model
    config = Coqpit(**filtered_config)
             ^^^^^^^^^^^^^^^^^^^^^^^^^
TypeError: Coqpit.__init__() got an unexpected keyword argument 'model'

2025-04-18 14:51:01,888 - INFO - Successfully imported Trainer, TrainerArgs, load_tts_samples, setup_model from TTS.bin.train_tts
2025-04-18 14:51:07,335 - INFO - Found config for Zhongli: voice_datasets\Zhongli\zhongli_config.json
2025-04-18 14:51:07,336 - INFO - Found 1 character configs in voice_datasets
2025-04-18 14:51:14,982 - INFO - Loaded configuration from voice_datasets\Zhongli\zhongli_config.json
2025-04-18 14:51:14,986 - INFO - Loaded configuration from voice_datasets\Zhongli\zhongli_config.json
2025-04-18 14:51:14,986 - INFO - Model tts_models/en/ek1/tacotron2 not found in cache. Attempting to download.
2025-04-18 14:51:14,999 - INFO - Successfully downloaded model: tts_models/en/ek1/tacotron2 to C:\Users\DRAGOHN/.cache/tts/tts_models--en--ek1--tacotron2
2025-04-18 14:51:14,999 - INFO - Using CPU for training.
2025-04-18 14:51:15,000 - INFO - Using training metadata file at: voice_datasets\Zhongli\metadata.csv
2025-04-18 14:51:15,001 - INFO - Using validation metadata file at: voice_datasets\Zhongli\valid.csv
2025-04-18 14:51:15,001 - ERROR - Training failed: Coqpit.__init__() got an unexpected keyword argument 'batch_size'
Traceback (most recent call last):
  File "D:\Scripts\EchoPersona\train_tts_model.py", line 284, in train_model
    config = Coqpit(**filtered_config)
             ^^^^^^^^^^^^^^^^^^^^^^^^^
TypeError: Coqpit.__init__() got an unexpected keyword argument 'batch_size'

2025-04-18 14:52:19,266 - INFO - Successfully imported Trainer, TrainerArgs, load_tts_samples, setup_model from TTS.bin.train_tts
2025-04-18 14:52:24,299 - INFO - Found config for Zhongli: voice_datasets\Zhongli\zhongli_config.json
2025-04-18 14:52:24,299 - INFO - Found 1 character configs in voice_datasets
2025-04-18 14:52:28,482 - INFO - Loaded configuration from voice_datasets\Zhongli\zhongli_config.json
2025-04-18 14:52:28,483 - INFO - Loaded configuration from voice_datasets\Zhongli\zhongli_config.json
2025-04-18 14:52:28,484 - INFO - Model tts_models/en/ek1/tacotron2 not found in cache. Attempting to download.
2025-04-18 14:52:28,496 - INFO - Successfully downloaded model: tts_models/en/ek1/tacotron2 to C:\Users\DRAGOHN/.cache/tts/tts_models--en--ek1--tacotron2
2025-04-18 14:52:28,496 - INFO - Using CPU for training.
2025-04-18 14:52:28,498 - INFO - Using training metadata file at: voice_datasets\Zhongli\metadata.csv
2025-04-18 14:52:28,499 - INFO - Using validation metadata file at: voice_datasets\Zhongli\valid.csv
2025-04-18 14:52:28,499 - ERROR - Training failed: Coqpit.__init__() got an unexpected keyword argument 'num_epochs'
Traceback (most recent call last):
  File "D:\Scripts\EchoPersona\train_tts_model.py", line 284, in train_model
    config = Coqpit(**filtered_config)
             ^^^^^^^^^^^^^^^^^^^^^^^^^
TypeError: Coqpit.__init__() got an unexpected keyword argument 'num_epochs'

2025-04-18 14:53:33,271 - INFO - Successfully imported Trainer, TrainerArgs, load_tts_samples, setup_model from TTS.bin.train_tts
2025-04-18 14:53:38,254 - INFO - Found config for Zhongli: voice_datasets\Zhongli\zhongli_config.json
2025-04-18 14:53:38,254 - INFO - Found 1 character configs in voice_datasets
2025-04-18 14:53:44,097 - INFO - Loaded configuration from voice_datasets\Zhongli\zhongli_config.json
2025-04-18 14:53:44,099 - INFO - Loaded configuration from voice_datasets\Zhongli\zhongli_config.json
2025-04-18 14:53:44,100 - INFO - Model tts_models/en/ek1/tacotron2 not found in cache. Attempting to download.
2025-04-18 14:53:44,112 - INFO - Successfully downloaded model: tts_models/en/ek1/tacotron2 to C:\Users\DRAGOHN/.cache/tts/tts_models--en--ek1--tacotron2
2025-04-18 14:53:44,112 - INFO - Using CPU for training.
2025-04-18 14:53:44,114 - INFO - Using training metadata file at: voice_datasets\Zhongli\metadata.csv
2025-04-18 14:53:44,114 - INFO - Using validation metadata file at: voice_datasets\Zhongli\valid.csv
2025-04-18 14:53:44,115 - ERROR - Training failed: Coqpit.__init__() got an unexpected keyword argument 'run_eval'
Traceback (most recent call last):
  File "D:\Scripts\EchoPersona\train_tts_model.py", line 284, in train_model
    config = Coqpit(**filtered_config)
             ^^^^^^^^^^^^^^^^^^^^^^^^^
TypeError: Coqpit.__init__() got an unexpected keyword argument 'run_eval'

2025-04-18 14:54:21,529 - INFO - Successfully imported Trainer, TrainerArgs, load_tts_samples, setup_model from TTS.bin.train_tts
2025-04-18 14:54:26,694 - INFO - Found config for Zhongli: voice_datasets\Zhongli\zhongli_config.json
2025-04-18 14:54:26,695 - INFO - Found 1 character configs in voice_datasets
2025-04-18 14:54:32,243 - INFO - Loaded configuration from voice_datasets\Zhongli\zhongli_config.json
2025-04-18 14:54:32,247 - INFO - Loaded configuration from voice_datasets\Zhongli\zhongli_config.json
2025-04-18 14:54:32,248 - INFO - Model tts_models/en/ek1/tacotron2 not found in cache. Attempting to download.
2025-04-18 14:54:32,262 - INFO - Successfully downloaded model: tts_models/en/ek1/tacotron2 to C:\Users\DRAGOHN/.cache/tts/tts_models--en--ek1--tacotron2
2025-04-18 14:54:32,263 - INFO - Using CPU for training.
2025-04-18 14:54:32,264 - INFO - Using training metadata file at: voice_datasets\Zhongli\metadata.csv
2025-04-18 14:54:32,265 - INFO - Using validation metadata file at: voice_datasets\Zhongli\valid.csv
2025-04-18 14:54:32,265 - ERROR - Training failed: Coqpit.__init__() got an unexpected keyword argument 'formatter'
Traceback (most recent call last):
  File "D:\Scripts\EchoPersona\train_tts_model.py", line 284, in train_model
    config = Coqpit(**filtered_config)
             ^^^^^^^^^^^^^^^^^^^^^^^^^
TypeError: Coqpit.__init__() got an unexpected keyword argument 'formatter'

2025-04-18 14:55:28,237 - INFO - Successfully imported Trainer, TrainerArgs, load_tts_samples, setup_model from TTS.bin.train_tts
2025-04-18 14:55:34,259 - INFO - Found config for Zhongli: voice_datasets\Zhongli\zhongli_config.json
2025-04-18 14:55:34,260 - INFO - Found 1 character configs in voice_datasets
2025-04-18 14:55:38,642 - INFO - Loaded configuration from voice_datasets\Zhongli\zhongli_config.json
2025-04-18 14:55:38,644 - INFO - Loaded configuration from voice_datasets\Zhongli\zhongli_config.json
2025-04-18 14:55:38,645 - INFO - Model tts_models/en/ek1/tacotron2 not found in cache. Attempting to download.
2025-04-18 14:55:38,657 - INFO - Successfully downloaded model: tts_models/en/ek1/tacotron2 to C:\Users\DRAGOHN/.cache/tts/tts_models--en--ek1--tacotron2
2025-04-18 14:55:38,657 - INFO - Using CPU for training.
2025-04-18 14:55:38,659 - INFO - Using training metadata file at: voice_datasets\Zhongli\metadata.csv
2025-04-18 14:55:38,660 - INFO - Using validation metadata file at: voice_datasets\Zhongli\valid.csv
2025-04-18 14:55:38,660 - ERROR - Training failed: Coqpit.__init__() got an unexpected keyword argument 'datasets'
Traceback (most recent call last):
  File "D:\Scripts\EchoPersona\train_tts_model.py", line 294, in train_model
    config = Coqpit(**filtered_config)
             ^^^^^^^^^^^^^^^^^^^^^^^^^
TypeError: Coqpit.__init__() got an unexpected keyword argument 'datasets'

2025-04-18 14:57:44,572 - INFO - Successfully imported Trainer, TrainerArgs, load_tts_samples, setup_model from TTS.bin.train_tts
2025-04-18 14:57:49,485 - INFO - Found config for Zhongli: voice_datasets\Zhongli\zhongli_config.json
2025-04-18 14:57:49,485 - INFO - Found 1 character configs in voice_datasets
2025-04-18 14:57:49,487 - INFO - Loaded configuration from voice_datasets\Zhongli\zhongli_config.json
2025-04-18 14:57:49,487 - INFO - Training model for Zhongli...
2025-04-18 14:57:49,488 - INFO - Loaded configuration from voice_datasets\Zhongli\zhongli_config.json
2025-04-18 14:57:49,488 - INFO - Model tts_models/en/ek1/tacotron2 not found in cache. Attempting to download.
2025-04-18 14:57:49,508 - INFO - Successfully downloaded model: tts_models/en/ek1/tacotron2 to C:\Users\DRAGOHN/.cache/tts/tts_models--en--ek1--tacotron2
2025-04-18 14:57:49,509 - INFO - Using CPU for training.
2025-04-18 14:57:49,510 - INFO - Using training metadata file at: voice_datasets\Zhongli\metadata.csv
2025-04-18 14:57:49,511 - INFO - Using validation metadata file at: voice_datasets\Zhongli\valid.csv
2025-04-18 14:57:49,512 - ERROR - Training failed: Coqpit.__init__() got an unexpected keyword argument 'formatter'
Traceback (most recent call last):
  File "D:\Scripts\EchoPersona\train_tts_model.py", line 294, in train_model
    config = Coqpit(**filtered_config)
             ^^^^^^^^^^^^^^^^^^^^^^^^^
TypeError: Coqpit.__init__() got an unexpected keyword argument 'formatter'

2025-04-18 14:57:49,512 - ERROR - Failed to process Zhongli: Coqpit.__init__() got an unexpected keyword argument 'formatter'
2025-04-18 15:00:19,035 - INFO - Successfully imported Trainer, TrainerArgs, load_tts_samples, setup_model from TTS.bin.train_tts
2025-04-18 15:00:23,927 - INFO - Found config for Zhongli: voice_datasets\Zhongli\zhongli_config.json
2025-04-18 15:00:23,927 - INFO - Found 1 character configs in voice_datasets
2025-04-18 15:00:23,927 - INFO - Loaded configuration from voice_datasets\Zhongli\zhongli_config.json
2025-04-18 15:00:23,928 - INFO - Training model for Zhongli...
2025-04-18 15:00:23,928 - INFO - Loaded configuration from voice_datasets\Zhongli\zhongli_config.json
2025-04-18 15:00:23,929 - INFO - Model tts_models/en/ek1/tacotron2 not found in cache. Attempting to download.
2025-04-18 15:00:23,948 - INFO - Successfully downloaded model: tts_models/en/ek1/tacotron2 to C:\Users\DRAGOHN/.cache/tts/tts_models--en--ek1--tacotron2
2025-04-18 15:00:23,948 - INFO - Using CPU for training.
2025-04-18 15:00:23,950 - INFO - Using training metadata file at: voice_datasets\Zhongli\metadata.csv
2025-04-18 15:00:23,950 - INFO - Using validation metadata file at: voice_datasets\Zhongli\valid.csv
2025-04-18 15:00:23,951 - ERROR - Training failed: Coqpit.__init__() got an unexpected keyword argument 'formatter'
Traceback (most recent call last):
  File "D:\Scripts\EchoPersona\train_tts_model.py", line 294, in train_model
    config = Coqpit(**filtered_config)
             ^^^^^^^^^^^^^^^^^^^^^^^^^
TypeError: Coqpit.__init__() got an unexpected keyword argument 'formatter'

2025-04-18 15:00:23,952 - ERROR - Failed to process Zhongli: Coqpit.__init__() got an unexpected keyword argument 'formatter'
2025-04-18 15:02:35,021 - INFO - Successfully imported Trainer, TrainerArgs, load_tts_samples, setup_model from TTS.bin.train_tts
2025-04-18 15:02:39,974 - INFO - Found config for Zhongli: voice_datasets\Zhongli\zhongli_config.json
2025-04-18 15:02:39,975 - INFO - Found 1 character configs in voice_datasets
2025-04-18 15:02:45,897 - INFO - Loaded configuration from voice_datasets\Zhongli\zhongli_config.json
2025-04-18 15:02:45,899 - INFO - Loaded configuration from voice_datasets\Zhongli\zhongli_config.json
2025-04-18 15:02:45,900 - INFO - Model tts_models/en/ek1/tacotron2 not found in cache. Attempting to download.
2025-04-18 15:02:45,913 - INFO - Successfully downloaded model: tts_models/en/ek1/tacotron2 to C:\Users\DRAGOHN/.cache/tts/tts_models--en--ek1--tacotron2
2025-04-18 15:02:45,913 - INFO - Using CPU for training.
2025-04-18 15:02:45,915 - INFO - Using training metadata file at: voice_datasets\Zhongli\metadata.csv
2025-04-18 15:02:45,915 - INFO - Using validation metadata file at: voice_datasets\Zhongli\valid.csv
2025-04-18 15:02:45,917 - ERROR - Training failed: Coqpit.__init__() got an unexpected keyword argument 'ignored_speakers'
Traceback (most recent call last):
  File "D:\Scripts\EchoPersona\train_tts_model.py", line 302, in train_model
    config = Coqpit(**filtered_config)
             ^^^^^^^^^^^^^^^^^^^^^^^^^
TypeError: Coqpit.__init__() got an unexpected keyword argument 'ignored_speakers'

2025-04-18 15:04:10,954 - INFO - Successfully imported Trainer, TrainerArgs, load_tts_samples, setup_model from TTS.bin.train_tts
2025-04-18 15:04:16,257 - INFO - Found config for Zhongli: voice_datasets\Zhongli\zhongli_config.json
2025-04-18 15:04:16,257 - INFO - Found 1 character configs in voice_datasets
2025-04-18 15:04:24,896 - INFO - Loaded configuration from voice_datasets\Zhongli\zhongli_config.json
2025-04-18 15:04:24,898 - INFO - Loaded configuration from voice_datasets\Zhongli\zhongli_config.json
2025-04-18 15:04:24,898 - INFO - Model tts_models/en/ek1/tacotron2 not found in cache. Attempting to download.
2025-04-18 15:04:24,912 - INFO - Successfully downloaded model: tts_models/en/ek1/tacotron2 to C:\Users\DRAGOHN/.cache/tts/tts_models--en--ek1--tacotron2
2025-04-18 15:04:24,912 - INFO - Using CPU for training.
2025-04-18 15:04:24,913 - INFO - Using training metadata file at: voice_datasets\Zhongli\metadata.csv
2025-04-18 15:04:24,914 - INFO - Using validation metadata file at: voice_datasets\Zhongli\valid.csv
2025-04-18 15:04:24,915 - ERROR - Training failed: Coqpit.__init__() got an unexpected keyword argument 'ignored_speakers'
Traceback (most recent call last):
  File "D:\Scripts\EchoPersona\train_tts_model.py", line 303, in train_model
    config = Coqpit(**filtered_config)
             ^^^^^^^^^^^^^^^^^^^^^^^^^
TypeError: Coqpit.__init__() got an unexpected keyword argument 'ignored_speakers'

2025-04-18 15:04:45,316 - INFO - Successfully imported Trainer, TrainerArgs, load_tts_samples, setup_model from TTS.bin.train_tts
2025-04-18 15:04:50,391 - INFO - Found config for Zhongli: voice_datasets\Zhongli\zhongli_config.json
2025-04-18 15:04:50,391 - INFO - Found 1 character configs in voice_datasets
2025-04-18 15:04:57,011 - INFO - Loaded configuration from voice_datasets\Zhongli\zhongli_config.json
2025-04-18 15:04:57,014 - INFO - Loaded configuration from voice_datasets\Zhongli\zhongli_config.json
2025-04-18 15:04:57,014 - INFO - Model tts_models/en/ek1/tacotron2 not found in cache. Attempting to download.
2025-04-18 15:04:57,027 - INFO - Successfully downloaded model: tts_models/en/ek1/tacotron2 to C:\Users\DRAGOHN/.cache/tts/tts_models--en--ek1--tacotron2
2025-04-18 15:04:57,028 - INFO - Using CPU for training.
2025-04-18 15:04:57,030 - INFO - Using training metadata file at: voice_datasets\Zhongli\metadata.csv
2025-04-18 15:04:57,030 - INFO - Using validation metadata file at: voice_datasets\Zhongli\valid.csv
2025-04-18 15:04:57,030 - INFO - Using Trainer.fit with dataset preprocessing from TTS.bin.train_tts
2025-04-18 15:04:57,031 - WARNING - Trainer.fit with preprocessing failed: [Errno 2] No such file or directory: 'voice_datasets\\Zhongli\\wavs\\metadata.csv'
Traceback (most recent call last):
  File "D:\Scripts\EchoPersona\train_tts_model.py", line 312, in train_model
    train_samples, eval_samples = load_tts_samples(
                                  ^^^^^^^^^^^^^^^^^
  File "D:\Scripts\EchoPersona\.venv\Lib\site-packages\TTS\tts\datasets\__init__.py", line 120, in load_tts_samples
    meta_data_train = formatter(root_path, meta_file_train, ignored_speakers=ignored_speakers)
                      ^^^^^^^^^^^^^^^^^^^^^^^^^^^^^^^^^^^^^^^^^^^^^^^^^^^^^^^^^^^^^^^^^^^^^^^^
  File "D:\Scripts\EchoPersona\.venv\Lib\site-packages\TTS\tts\datasets\formatters.py", line 197, in ljspeech
    with open(txt_file, "r", encoding="utf-8") as ttf:
         ^^^^^^^^^^^^^^^^^^^^^^^^^^^^^^^^^^^^^
FileNotFoundError: [Errno 2] No such file or directory: 'voice_datasets\\Zhongli\\wavs\\metadata.csv'

2025-04-18 15:04:57,032 - INFO - Attempting manual dataset handling with Trainer.fit
2025-04-18 15:04:57,032 - INFO - Loaded configuration from voice_datasets\Zhongli\zhongli_config.json
2025-04-18 15:04:57,037 - ERROR - Manual dataset handling failed: 'dict' object has no attribute 'parse_known_args'
Traceback (most recent call last):
  File "D:\Scripts\EchoPersona\train_tts_model.py", line 312, in train_model
    train_samples, eval_samples = load_tts_samples(
                                  ^^^^^^^^^^^^^^^^^
  File "D:\Scripts\EchoPersona\.venv\Lib\site-packages\TTS\tts\datasets\__init__.py", line 120, in load_tts_samples
    meta_data_train = formatter(root_path, meta_file_train, ignored_speakers=ignored_speakers)
                      ^^^^^^^^^^^^^^^^^^^^^^^^^^^^^^^^^^^^^^^^^^^^^^^^^^^^^^^^^^^^^^^^^^^^^^^^
  File "D:\Scripts\EchoPersona\.venv\Lib\site-packages\TTS\tts\datasets\formatters.py", line 197, in ljspeech
    with open(txt_file, "r", encoding="utf-8") as ttf:
         ^^^^^^^^^^^^^^^^^^^^^^^^^^^^^^^^^^^^^
FileNotFoundError: [Errno 2] No such file or directory: 'voice_datasets\\Zhongli\\wavs\\metadata.csv'

During handling of the above exception, another exception occurred:

Traceback (most recent call last):
  File "D:\Scripts\EchoPersona\train_tts_model.py", line 367, in train_model
    trainer = Trainer(
              ^^^^^^^^
  File "D:\Scripts\EchoPersona\.venv\Lib\site-packages\trainer\trainer.py", line 400, in __init__
    config, new_fields = self.init_training(args, coqpit_overrides, config)
                         ^^^^^^^^^^^^^^^^^^^^^^^^^^^^^^^^^^^^^^^^^^^^^^^^^^
  File "D:\Scripts\EchoPersona\.venv\Lib\site-packages\trainer\trainer.py", line 745, in init_training
    config.parse_known_args(coqpit_overrides, relaxed_parser=True)
    ^^^^^^^^^^^^^^^^^^^^^^^
AttributeError: 'dict' object has no attribute 'parse_known_args'

2025-04-18 15:04:57,040 - ERROR - Training failed: All Trainer.fit attempts failed
Traceback (most recent call last):
  File "D:\Scripts\EchoPersona\train_tts_model.py", line 312, in train_model
    train_samples, eval_samples = load_tts_samples(
                                  ^^^^^^^^^^^^^^^^^
  File "D:\Scripts\EchoPersona\.venv\Lib\site-packages\TTS\tts\datasets\__init__.py", line 120, in load_tts_samples
    meta_data_train = formatter(root_path, meta_file_train, ignored_speakers=ignored_speakers)
                      ^^^^^^^^^^^^^^^^^^^^^^^^^^^^^^^^^^^^^^^^^^^^^^^^^^^^^^^^^^^^^^^^^^^^^^^^
  File "D:\Scripts\EchoPersona\.venv\Lib\site-packages\TTS\tts\datasets\formatters.py", line 197, in ljspeech
    with open(txt_file, "r", encoding="utf-8") as ttf:
         ^^^^^^^^^^^^^^^^^^^^^^^^^^^^^^^^^^^^^
FileNotFoundError: [Errno 2] No such file or directory: 'voice_datasets\\Zhongli\\wavs\\metadata.csv'

During handling of the above exception, another exception occurred:

Traceback (most recent call last):
  File "D:\Scripts\EchoPersona\train_tts_model.py", line 367, in train_model
    trainer = Trainer(
              ^^^^^^^^
  File "D:\Scripts\EchoPersona\.venv\Lib\site-packages\trainer\trainer.py", line 400, in __init__
    config, new_fields = self.init_training(args, coqpit_overrides, config)
                         ^^^^^^^^^^^^^^^^^^^^^^^^^^^^^^^^^^^^^^^^^^^^^^^^^^
  File "D:\Scripts\EchoPersona\.venv\Lib\site-packages\trainer\trainer.py", line 745, in init_training
    config.parse_known_args(coqpit_overrides, relaxed_parser=True)
    ^^^^^^^^^^^^^^^^^^^^^^^
AttributeError: 'dict' object has no attribute 'parse_known_args'

During handling of the above exception, another exception occurred:

Traceback (most recent call last):
  File "D:\Scripts\EchoPersona\train_tts_model.py", line 386, in train_model
    raise RuntimeError("All Trainer.fit attempts failed")
RuntimeError: All Trainer.fit attempts failed

2025-04-18 15:09:25,190 - INFO - Successfully imported Trainer, TrainerArgs, load_tts_samples, setup_model from TTS.bin.train_tts
2025-04-18 15:09:30,295 - INFO - Found config for Zhongli: voice_datasets\Zhongli\zhongli_config.json
2025-04-18 15:09:30,295 - INFO - Found 1 character configs in voice_datasets
2025-04-18 15:09:35,205 - INFO - Loaded configuration from voice_datasets\Zhongli\zhongli_config.json
2025-04-18 15:09:35,208 - INFO - Loaded configuration from voice_datasets\Zhongli\zhongli_config.json
2025-04-18 15:09:35,209 - INFO - Model tts_models/en/ek1/tacotron2 not found in cache. Attempting to download.
2025-04-18 15:09:35,221 - INFO - Successfully downloaded model: tts_models/en/ek1/tacotron2 to C:\Users\DRAGOHN/.cache/tts/tts_models--en--ek1--tacotron2
2025-04-18 15:09:35,221 - INFO - Using CPU for training.
2025-04-18 15:09:35,224 - INFO - Using training metadata file at: voice_datasets\Zhongli\metadata.csv
2025-04-18 15:09:35,224 - INFO - Using validation metadata file at: voice_datasets\Zhongli\valid.csv
2025-04-18 15:09:35,224 - INFO - Using Trainer.fit with dataset preprocessing from TTS.bin.train_tts
2025-04-18 15:09:35,225 - WARNING - Trainer.fit with preprocessing failed: [Errno 2] No such file or directory: 'voice_datasets\\Zhongli\\wavs\\metadata.csv'
Traceback (most recent call last):
  File "D:\Scripts\EchoPersona\train_tts_model.py", line 313, in train_model
    train_samples, eval_samples = load_tts_samples(
                                  ^^^^^^^^^^^^^^^^^
  File "D:\Scripts\EchoPersona\.venv\Lib\site-packages\TTS\tts\datasets\__init__.py", line 120, in load_tts_samples
    meta_data_train = formatter(root_path, meta_file_train, ignored_speakers=ignored_speakers)
                      ^^^^^^^^^^^^^^^^^^^^^^^^^^^^^^^^^^^^^^^^^^^^^^^^^^^^^^^^^^^^^^^^^^^^^^^^
  File "D:\Scripts\EchoPersona\.venv\Lib\site-packages\TTS\tts\datasets\formatters.py", line 197, in ljspeech
    with open(txt_file, "r", encoding="utf-8") as ttf:
         ^^^^^^^^^^^^^^^^^^^^^^^^^^^^^^^^^^^^^
FileNotFoundError: [Errno 2] No such file or directory: 'voice_datasets\\Zhongli\\wavs\\metadata.csv'

2025-04-18 15:09:35,226 - INFO - Attempting manual dataset handling with Trainer.fit
2025-04-18 15:09:35,226 - INFO - Loaded configuration from voice_datasets\Zhongli\zhongli_config.json
2025-04-18 15:09:35,230 - ERROR - Manual dataset handling failed: 'dict' object has no attribute 'parse_known_args'
Traceback (most recent call last):
  File "D:\Scripts\EchoPersona\train_tts_model.py", line 313, in train_model
    train_samples, eval_samples = load_tts_samples(
                                  ^^^^^^^^^^^^^^^^^
  File "D:\Scripts\EchoPersona\.venv\Lib\site-packages\TTS\tts\datasets\__init__.py", line 120, in load_tts_samples
    meta_data_train = formatter(root_path, meta_file_train, ignored_speakers=ignored_speakers)
                      ^^^^^^^^^^^^^^^^^^^^^^^^^^^^^^^^^^^^^^^^^^^^^^^^^^^^^^^^^^^^^^^^^^^^^^^^
  File "D:\Scripts\EchoPersona\.venv\Lib\site-packages\TTS\tts\datasets\formatters.py", line 197, in ljspeech
    with open(txt_file, "r", encoding="utf-8") as ttf:
         ^^^^^^^^^^^^^^^^^^^^^^^^^^^^^^^^^^^^^
FileNotFoundError: [Errno 2] No such file or directory: 'voice_datasets\\Zhongli\\wavs\\metadata.csv'

During handling of the above exception, another exception occurred:

Traceback (most recent call last):
  File "D:\Scripts\EchoPersona\train_tts_model.py", line 368, in train_model
    trainer = Trainer(
              ^^^^^^^^
  File "D:\Scripts\EchoPersona\.venv\Lib\site-packages\trainer\trainer.py", line 400, in __init__
    config, new_fields = self.init_training(args, coqpit_overrides, config)
                         ^^^^^^^^^^^^^^^^^^^^^^^^^^^^^^^^^^^^^^^^^^^^^^^^^^
  File "D:\Scripts\EchoPersona\.venv\Lib\site-packages\trainer\trainer.py", line 745, in init_training
    config.parse_known_args(coqpit_overrides, relaxed_parser=True)
    ^^^^^^^^^^^^^^^^^^^^^^^
AttributeError: 'dict' object has no attribute 'parse_known_args'

2025-04-18 15:09:35,232 - ERROR - Training failed: All Trainer.fit attempts failed
Traceback (most recent call last):
  File "D:\Scripts\EchoPersona\train_tts_model.py", line 313, in train_model
    train_samples, eval_samples = load_tts_samples(
                                  ^^^^^^^^^^^^^^^^^
  File "D:\Scripts\EchoPersona\.venv\Lib\site-packages\TTS\tts\datasets\__init__.py", line 120, in load_tts_samples
    meta_data_train = formatter(root_path, meta_file_train, ignored_speakers=ignored_speakers)
                      ^^^^^^^^^^^^^^^^^^^^^^^^^^^^^^^^^^^^^^^^^^^^^^^^^^^^^^^^^^^^^^^^^^^^^^^^
  File "D:\Scripts\EchoPersona\.venv\Lib\site-packages\TTS\tts\datasets\formatters.py", line 197, in ljspeech
    with open(txt_file, "r", encoding="utf-8") as ttf:
         ^^^^^^^^^^^^^^^^^^^^^^^^^^^^^^^^^^^^^
FileNotFoundError: [Errno 2] No such file or directory: 'voice_datasets\\Zhongli\\wavs\\metadata.csv'

During handling of the above exception, another exception occurred:

Traceback (most recent call last):
  File "D:\Scripts\EchoPersona\train_tts_model.py", line 368, in train_model
    trainer = Trainer(
              ^^^^^^^^
  File "D:\Scripts\EchoPersona\.venv\Lib\site-packages\trainer\trainer.py", line 400, in __init__
    config, new_fields = self.init_training(args, coqpit_overrides, config)
                         ^^^^^^^^^^^^^^^^^^^^^^^^^^^^^^^^^^^^^^^^^^^^^^^^^^
  File "D:\Scripts\EchoPersona\.venv\Lib\site-packages\trainer\trainer.py", line 745, in init_training
    config.parse_known_args(coqpit_overrides, relaxed_parser=True)
    ^^^^^^^^^^^^^^^^^^^^^^^
AttributeError: 'dict' object has no attribute 'parse_known_args'

During handling of the above exception, another exception occurred:

Traceback (most recent call last):
  File "D:\Scripts\EchoPersona\train_tts_model.py", line 387, in train_model
    raise RuntimeError("All Trainer.fit attempts failed")
RuntimeError: All Trainer.fit attempts failed

2025-04-18 15:10:50,322 - INFO - Successfully imported Trainer, TrainerArgs, load_tts_samples, setup_model from TTS.bin.train_tts
2025-04-18 15:10:55,471 - INFO - Found config for Zhongli: voice_datasets\Zhongli\zhongli_config.json
2025-04-18 15:10:55,471 - INFO - Found 1 character configs in voice_datasets
2025-04-18 15:11:00,163 - INFO - Loaded configuration from voice_datasets\Zhongli\zhongli_config.json
2025-04-18 15:11:00,166 - INFO - Loaded configuration from voice_datasets\Zhongli\zhongli_config.json
2025-04-18 15:11:00,166 - INFO - Model tts_models/en/ek1/tacotron2 not found in cache. Attempting to download.
2025-04-18 15:11:00,179 - INFO - Successfully downloaded model: tts_models/en/ek1/tacotron2 to C:\Users\DRAGOHN/.cache/tts/tts_models--en--ek1--tacotron2
2025-04-18 15:11:00,180 - INFO - Using CPU for training.
2025-04-18 15:11:00,181 - INFO - Using training metadata file at: voice_datasets\Zhongli\metadata.csv
2025-04-18 15:11:00,182 - INFO - Using validation metadata file at: voice_datasets\Zhongli\valid.csv
2025-04-18 15:11:00,182 - INFO - Using Trainer.fit with dataset preprocessing from TTS.bin.train_tts
2025-04-18 15:11:00,184 - WARNING - Trainer.fit with preprocessing failed: [Errno 2] No such file or directory: 'voice_datasets\\Zhongli\\wavs\\metadata.csv'
Traceback (most recent call last):
  File "D:\Scripts\EchoPersona\train_tts_model.py", line 315, in train_model
    train_samples, eval_samples = load_tts_samples(
                                  ^^^^^^^^^^^^^^^^^
  File "D:\Scripts\EchoPersona\.venv\Lib\site-packages\TTS\tts\datasets\__init__.py", line 120, in load_tts_samples
    meta_data_train = formatter(root_path, meta_file_train, ignored_speakers=ignored_speakers)
                      ^^^^^^^^^^^^^^^^^^^^^^^^^^^^^^^^^^^^^^^^^^^^^^^^^^^^^^^^^^^^^^^^^^^^^^^^
  File "D:\Scripts\EchoPersona\.venv\Lib\site-packages\TTS\tts\datasets\formatters.py", line 197, in ljspeech
    with open(txt_file, "r", encoding="utf-8") as ttf:
         ^^^^^^^^^^^^^^^^^^^^^^^^^^^^^^^^^^^^^
FileNotFoundError: [Errno 2] No such file or directory: 'voice_datasets\\Zhongli\\wavs\\metadata.csv'

2025-04-18 15:11:00,184 - INFO - Attempting manual dataset handling with Trainer.fit
2025-04-18 15:11:00,184 - INFO - Loaded configuration from voice_datasets\Zhongli\zhongli_config.json
2025-04-18 15:11:00,189 - ERROR - Manual dataset handling failed: 'dict' object has no attribute 'parse_known_args'
Traceback (most recent call last):
  File "D:\Scripts\EchoPersona\train_tts_model.py", line 315, in train_model
    train_samples, eval_samples = load_tts_samples(
                                  ^^^^^^^^^^^^^^^^^
  File "D:\Scripts\EchoPersona\.venv\Lib\site-packages\TTS\tts\datasets\__init__.py", line 120, in load_tts_samples
    meta_data_train = formatter(root_path, meta_file_train, ignored_speakers=ignored_speakers)
                      ^^^^^^^^^^^^^^^^^^^^^^^^^^^^^^^^^^^^^^^^^^^^^^^^^^^^^^^^^^^^^^^^^^^^^^^^
  File "D:\Scripts\EchoPersona\.venv\Lib\site-packages\TTS\tts\datasets\formatters.py", line 197, in ljspeech
    with open(txt_file, "r", encoding="utf-8") as ttf:
         ^^^^^^^^^^^^^^^^^^^^^^^^^^^^^^^^^^^^^
FileNotFoundError: [Errno 2] No such file or directory: 'voice_datasets\\Zhongli\\wavs\\metadata.csv'

During handling of the above exception, another exception occurred:

Traceback (most recent call last):
  File "D:\Scripts\EchoPersona\train_tts_model.py", line 370, in train_model
    trainer = Trainer(
              ^^^^^^^^
  File "D:\Scripts\EchoPersona\.venv\Lib\site-packages\trainer\trainer.py", line 400, in __init__
    config, new_fields = self.init_training(args, coqpit_overrides, config)
                         ^^^^^^^^^^^^^^^^^^^^^^^^^^^^^^^^^^^^^^^^^^^^^^^^^^
  File "D:\Scripts\EchoPersona\.venv\Lib\site-packages\trainer\trainer.py", line 745, in init_training
    config.parse_known_args(coqpit_overrides, relaxed_parser=True)
    ^^^^^^^^^^^^^^^^^^^^^^^
AttributeError: 'dict' object has no attribute 'parse_known_args'

2025-04-18 15:11:00,192 - ERROR - Training failed: All Trainer.fit attempts failed
Traceback (most recent call last):
  File "D:\Scripts\EchoPersona\train_tts_model.py", line 315, in train_model
    train_samples, eval_samples = load_tts_samples(
                                  ^^^^^^^^^^^^^^^^^
  File "D:\Scripts\EchoPersona\.venv\Lib\site-packages\TTS\tts\datasets\__init__.py", line 120, in load_tts_samples
    meta_data_train = formatter(root_path, meta_file_train, ignored_speakers=ignored_speakers)
                      ^^^^^^^^^^^^^^^^^^^^^^^^^^^^^^^^^^^^^^^^^^^^^^^^^^^^^^^^^^^^^^^^^^^^^^^^
  File "D:\Scripts\EchoPersona\.venv\Lib\site-packages\TTS\tts\datasets\formatters.py", line 197, in ljspeech
    with open(txt_file, "r", encoding="utf-8") as ttf:
         ^^^^^^^^^^^^^^^^^^^^^^^^^^^^^^^^^^^^^
FileNotFoundError: [Errno 2] No such file or directory: 'voice_datasets\\Zhongli\\wavs\\metadata.csv'

During handling of the above exception, another exception occurred:

Traceback (most recent call last):
  File "D:\Scripts\EchoPersona\train_tts_model.py", line 370, in train_model
    trainer = Trainer(
              ^^^^^^^^
  File "D:\Scripts\EchoPersona\.venv\Lib\site-packages\trainer\trainer.py", line 400, in __init__
    config, new_fields = self.init_training(args, coqpit_overrides, config)
                         ^^^^^^^^^^^^^^^^^^^^^^^^^^^^^^^^^^^^^^^^^^^^^^^^^^
  File "D:\Scripts\EchoPersona\.venv\Lib\site-packages\trainer\trainer.py", line 745, in init_training
    config.parse_known_args(coqpit_overrides, relaxed_parser=True)
    ^^^^^^^^^^^^^^^^^^^^^^^
AttributeError: 'dict' object has no attribute 'parse_known_args'

During handling of the above exception, another exception occurred:

Traceback (most recent call last):
  File "D:\Scripts\EchoPersona\train_tts_model.py", line 389, in train_model
    raise RuntimeError("All Trainer.fit attempts failed")
RuntimeError: All Trainer.fit attempts failed

2025-04-18 15:14:15,147 - INFO - Successfully imported Trainer, TrainerArgs, load_tts_samples, setup_model from TTS.bin.train_tts
2025-04-18 15:14:20,427 - INFO - Found config for Zhongli: voice_datasets\Zhongli\zhongli_config.json
2025-04-18 15:14:20,428 - INFO - Found 1 character configs in voice_datasets
2025-04-18 15:14:26,658 - INFO - Loaded configuration from voice_datasets\Zhongli\zhongli_config.json
2025-04-18 15:14:26,660 - INFO - Loaded configuration from voice_datasets\Zhongli\zhongli_config.json
2025-04-18 15:14:26,661 - INFO - Model tts_models/en/ek1/tacotron2 not found in cache. Attempting to download.
2025-04-18 15:14:26,673 - INFO - Successfully downloaded model: tts_models/en/ek1/tacotron2 to C:\Users\DRAGOHN/.cache/tts/tts_models--en--ek1--tacotron2
2025-04-18 15:14:26,674 - INFO - Using CPU for training.
2025-04-18 15:14:26,675 - INFO - Using training metadata file at: voice_datasets\Zhongli\metadata.csv
2025-04-18 15:14:26,675 - INFO - Using validation metadata file at: voice_datasets\Zhongli\valid.csv
2025-04-18 15:14:26,676 - INFO - Using Trainer.fit with dataset preprocessing from TTS.bin.train_tts
2025-04-18 15:14:26,677 - WARNING - Trainer.fit with preprocessing failed: [Errno 2] No such file or directory: 'voice_datasets\\Zhongli\\wavs\\metadata.csv'
Traceback (most recent call last):
  File "D:\Scripts\EchoPersona\train_tts_model.py", line 315, in train_model
    train_samples, eval_samples = load_tts_samples(
                                  ^^^^^^^^^^^^^^^^^
  File "D:\Scripts\EchoPersona\.venv\Lib\site-packages\TTS\tts\datasets\__init__.py", line 120, in load_tts_samples
    meta_data_train = formatter(root_path, meta_file_train, ignored_speakers=ignored_speakers)
                      ^^^^^^^^^^^^^^^^^^^^^^^^^^^^^^^^^^^^^^^^^^^^^^^^^^^^^^^^^^^^^^^^^^^^^^^^
  File "D:\Scripts\EchoPersona\.venv\Lib\site-packages\TTS\tts\datasets\formatters.py", line 197, in ljspeech
    with open(txt_file, "r", encoding="utf-8") as ttf:
         ^^^^^^^^^^^^^^^^^^^^^^^^^^^^^^^^^^^^^
FileNotFoundError: [Errno 2] No such file or directory: 'voice_datasets\\Zhongli\\wavs\\metadata.csv'

2025-04-18 15:14:26,677 - INFO - Attempting manual dataset handling with Trainer.fit
2025-04-18 15:14:26,679 - INFO - Loaded configuration from voice_datasets\Zhongli\zhongli_config.json
2025-04-18 15:14:26,682 - ERROR - Manual dataset handling failed: 'dict' object has no attribute 'parse_known_args'
Traceback (most recent call last):
  File "D:\Scripts\EchoPersona\train_tts_model.py", line 315, in train_model
    train_samples, eval_samples = load_tts_samples(
                                  ^^^^^^^^^^^^^^^^^
  File "D:\Scripts\EchoPersona\.venv\Lib\site-packages\TTS\tts\datasets\__init__.py", line 120, in load_tts_samples
    meta_data_train = formatter(root_path, meta_file_train, ignored_speakers=ignored_speakers)
                      ^^^^^^^^^^^^^^^^^^^^^^^^^^^^^^^^^^^^^^^^^^^^^^^^^^^^^^^^^^^^^^^^^^^^^^^^
  File "D:\Scripts\EchoPersona\.venv\Lib\site-packages\TTS\tts\datasets\formatters.py", line 197, in ljspeech
    with open(txt_file, "r", encoding="utf-8") as ttf:
         ^^^^^^^^^^^^^^^^^^^^^^^^^^^^^^^^^^^^^
FileNotFoundError: [Errno 2] No such file or directory: 'voice_datasets\\Zhongli\\wavs\\metadata.csv'

During handling of the above exception, another exception occurred:

Traceback (most recent call last):
  File "D:\Scripts\EchoPersona\train_tts_model.py", line 371, in train_model
    trainer = Trainer(
              ^^^^^^^^
  File "D:\Scripts\EchoPersona\.venv\Lib\site-packages\trainer\trainer.py", line 400, in __init__
    config, new_fields = self.init_training(args, coqpit_overrides, config)
                         ^^^^^^^^^^^^^^^^^^^^^^^^^^^^^^^^^^^^^^^^^^^^^^^^^^
  File "D:\Scripts\EchoPersona\.venv\Lib\site-packages\trainer\trainer.py", line 745, in init_training
    config.parse_known_args(coqpit_overrides, relaxed_parser=True)
    ^^^^^^^^^^^^^^^^^^^^^^^
AttributeError: 'dict' object has no attribute 'parse_known_args'

2025-04-18 15:14:26,686 - ERROR - Training failed: All Trainer.fit attempts failed
Traceback (most recent call last):
  File "D:\Scripts\EchoPersona\train_tts_model.py", line 315, in train_model
    train_samples, eval_samples = load_tts_samples(
                                  ^^^^^^^^^^^^^^^^^
  File "D:\Scripts\EchoPersona\.venv\Lib\site-packages\TTS\tts\datasets\__init__.py", line 120, in load_tts_samples
    meta_data_train = formatter(root_path, meta_file_train, ignored_speakers=ignored_speakers)
                      ^^^^^^^^^^^^^^^^^^^^^^^^^^^^^^^^^^^^^^^^^^^^^^^^^^^^^^^^^^^^^^^^^^^^^^^^
  File "D:\Scripts\EchoPersona\.venv\Lib\site-packages\TTS\tts\datasets\formatters.py", line 197, in ljspeech
    with open(txt_file, "r", encoding="utf-8") as ttf:
         ^^^^^^^^^^^^^^^^^^^^^^^^^^^^^^^^^^^^^
FileNotFoundError: [Errno 2] No such file or directory: 'voice_datasets\\Zhongli\\wavs\\metadata.csv'

During handling of the above exception, another exception occurred:

Traceback (most recent call last):
  File "D:\Scripts\EchoPersona\train_tts_model.py", line 371, in train_model
    trainer = Trainer(
              ^^^^^^^^
  File "D:\Scripts\EchoPersona\.venv\Lib\site-packages\trainer\trainer.py", line 400, in __init__
    config, new_fields = self.init_training(args, coqpit_overrides, config)
                         ^^^^^^^^^^^^^^^^^^^^^^^^^^^^^^^^^^^^^^^^^^^^^^^^^^
  File "D:\Scripts\EchoPersona\.venv\Lib\site-packages\trainer\trainer.py", line 745, in init_training
    config.parse_known_args(coqpit_overrides, relaxed_parser=True)
    ^^^^^^^^^^^^^^^^^^^^^^^
AttributeError: 'dict' object has no attribute 'parse_known_args'

During handling of the above exception, another exception occurred:

Traceback (most recent call last):
  File "D:\Scripts\EchoPersona\train_tts_model.py", line 390, in train_model
    raise RuntimeError("All Trainer.fit attempts failed")
RuntimeError: All Trainer.fit attempts failed

2025-04-18 15:15:39,034 - INFO - Successfully imported Trainer, TrainerArgs, load_tts_samples, setup_model from TTS.bin.train_tts
2025-04-18 15:15:44,333 - INFO - Found config for Zhongli: voice_datasets\Zhongli\zhongli_config.json
2025-04-18 15:15:44,334 - INFO - Found 1 character configs in voice_datasets
2025-04-18 15:15:48,134 - INFO - Loaded configuration from voice_datasets\Zhongli\zhongli_config.json
2025-04-18 15:15:48,137 - INFO - Loaded configuration from voice_datasets\Zhongli\zhongli_config.json
2025-04-18 15:15:48,138 - INFO - Model tts_models/en/ek1/tacotron2 not found in cache. Attempting to download.
2025-04-18 15:15:48,150 - INFO - Successfully downloaded model: tts_models/en/ek1/tacotron2 to C:\Users\DRAGOHN/.cache/tts/tts_models--en--ek1--tacotron2
2025-04-18 15:15:48,150 - INFO - Using CPU for training.
2025-04-18 15:15:48,151 - INFO - Using training metadata file at: voice_datasets\Zhongli\metadata.csv
2025-04-18 15:15:48,151 - INFO - Using validation metadata file at: voice_datasets\Zhongli\valid.csv
2025-04-18 15:15:48,152 - INFO - Using Trainer.fit with dataset preprocessing from TTS.bin.train_tts
2025-04-18 15:15:48,154 - WARNING - Trainer.fit with preprocessing failed: [Errno 2] No such file or directory: 'voice_datasets\\Zhongli\\wavs\\metadata.csv'
Traceback (most recent call last):
  File "D:\Scripts\EchoPersona\train_tts_model.py", line 315, in train_model
    train_samples, eval_samples = load_tts_samples(
                                  ^^^^^^^^^^^^^^^^^
  File "D:\Scripts\EchoPersona\.venv\Lib\site-packages\TTS\tts\datasets\__init__.py", line 120, in load_tts_samples
    meta_data_train = formatter(root_path, meta_file_train, ignored_speakers=ignored_speakers)
                      ^^^^^^^^^^^^^^^^^^^^^^^^^^^^^^^^^^^^^^^^^^^^^^^^^^^^^^^^^^^^^^^^^^^^^^^^
  File "D:\Scripts\EchoPersona\.venv\Lib\site-packages\TTS\tts\datasets\formatters.py", line 197, in ljspeech
    with open(txt_file, "r", encoding="utf-8") as ttf:
         ^^^^^^^^^^^^^^^^^^^^^^^^^^^^^^^^^^^^^
FileNotFoundError: [Errno 2] No such file or directory: 'voice_datasets\\Zhongli\\wavs\\metadata.csv'

2025-04-18 15:15:48,154 - INFO - Attempting manual dataset handling with Trainer.fit
2025-04-18 15:15:48,155 - INFO - Loaded configuration from voice_datasets\Zhongli\zhongli_config.json
2025-04-18 15:15:48,160 - ERROR - Manual dataset handling failed: 'dict' object has no attribute 'parse_known_args'
Traceback (most recent call last):
  File "D:\Scripts\EchoPersona\train_tts_model.py", line 315, in train_model
    train_samples, eval_samples = load_tts_samples(
                                  ^^^^^^^^^^^^^^^^^
  File "D:\Scripts\EchoPersona\.venv\Lib\site-packages\TTS\tts\datasets\__init__.py", line 120, in load_tts_samples
    meta_data_train = formatter(root_path, meta_file_train, ignored_speakers=ignored_speakers)
                      ^^^^^^^^^^^^^^^^^^^^^^^^^^^^^^^^^^^^^^^^^^^^^^^^^^^^^^^^^^^^^^^^^^^^^^^^
  File "D:\Scripts\EchoPersona\.venv\Lib\site-packages\TTS\tts\datasets\formatters.py", line 197, in ljspeech
    with open(txt_file, "r", encoding="utf-8") as ttf:
         ^^^^^^^^^^^^^^^^^^^^^^^^^^^^^^^^^^^^^
FileNotFoundError: [Errno 2] No such file or directory: 'voice_datasets\\Zhongli\\wavs\\metadata.csv'

During handling of the above exception, another exception occurred:

Traceback (most recent call last):
  File "D:\Scripts\EchoPersona\train_tts_model.py", line 371, in train_model
    trainer = Trainer(
              ^^^^^^^^
  File "D:\Scripts\EchoPersona\.venv\Lib\site-packages\trainer\trainer.py", line 400, in __init__
    config, new_fields = self.init_training(args, coqpit_overrides, config)
                         ^^^^^^^^^^^^^^^^^^^^^^^^^^^^^^^^^^^^^^^^^^^^^^^^^^
  File "D:\Scripts\EchoPersona\.venv\Lib\site-packages\trainer\trainer.py", line 745, in init_training
    config.parse_known_args(coqpit_overrides, relaxed_parser=True)
    ^^^^^^^^^^^^^^^^^^^^^^^
AttributeError: 'dict' object has no attribute 'parse_known_args'

2025-04-18 15:15:48,162 - ERROR - Training failed: All Trainer.fit attempts failed
Traceback (most recent call last):
  File "D:\Scripts\EchoPersona\train_tts_model.py", line 315, in train_model
    train_samples, eval_samples = load_tts_samples(
                                  ^^^^^^^^^^^^^^^^^
  File "D:\Scripts\EchoPersona\.venv\Lib\site-packages\TTS\tts\datasets\__init__.py", line 120, in load_tts_samples
    meta_data_train = formatter(root_path, meta_file_train, ignored_speakers=ignored_speakers)
                      ^^^^^^^^^^^^^^^^^^^^^^^^^^^^^^^^^^^^^^^^^^^^^^^^^^^^^^^^^^^^^^^^^^^^^^^^
  File "D:\Scripts\EchoPersona\.venv\Lib\site-packages\TTS\tts\datasets\formatters.py", line 197, in ljspeech
    with open(txt_file, "r", encoding="utf-8") as ttf:
         ^^^^^^^^^^^^^^^^^^^^^^^^^^^^^^^^^^^^^
FileNotFoundError: [Errno 2] No such file or directory: 'voice_datasets\\Zhongli\\wavs\\metadata.csv'

During handling of the above exception, another exception occurred:

Traceback (most recent call last):
  File "D:\Scripts\EchoPersona\train_tts_model.py", line 371, in train_model
    trainer = Trainer(
              ^^^^^^^^
  File "D:\Scripts\EchoPersona\.venv\Lib\site-packages\trainer\trainer.py", line 400, in __init__
    config, new_fields = self.init_training(args, coqpit_overrides, config)
                         ^^^^^^^^^^^^^^^^^^^^^^^^^^^^^^^^^^^^^^^^^^^^^^^^^^
  File "D:\Scripts\EchoPersona\.venv\Lib\site-packages\trainer\trainer.py", line 745, in init_training
    config.parse_known_args(coqpit_overrides, relaxed_parser=True)
    ^^^^^^^^^^^^^^^^^^^^^^^
AttributeError: 'dict' object has no attribute 'parse_known_args'

During handling of the above exception, another exception occurred:

Traceback (most recent call last):
  File "D:\Scripts\EchoPersona\train_tts_model.py", line 390, in train_model
    raise RuntimeError("All Trainer.fit attempts failed")
RuntimeError: All Trainer.fit attempts failed

2025-04-18 15:17:08,110 - INFO - Successfully imported Trainer, TrainerArgs, load_tts_samples, setup_model from TTS.bin.train_tts
2025-04-18 15:17:13,287 - INFO - Found config for Zhongli: voice_datasets\Zhongli\zhongli_config.json
2025-04-18 15:17:13,287 - INFO - Found 1 character configs in voice_datasets
2025-04-18 15:17:19,070 - INFO - Loaded configuration from voice_datasets\Zhongli\zhongli_config.json
2025-04-18 15:17:19,071 - INFO - Loaded configuration from voice_datasets\Zhongli\zhongli_config.json
2025-04-18 15:17:19,073 - INFO - Model tts_models/en/ek1/tacotron2 not found in cache. Attempting to download.
2025-04-18 15:17:19,085 - INFO - Successfully downloaded model: tts_models/en/ek1/tacotron2 to C:\Users\DRAGOHN/.cache/tts/tts_models--en--ek1--tacotron2
2025-04-18 15:17:19,085 - INFO - Using CPU for training.
2025-04-18 15:17:19,086 - INFO - Using training metadata file at: voice_datasets\Zhongli\metadata.csv
2025-04-18 15:17:19,088 - INFO - Using validation metadata file at: voice_datasets\Zhongli\valid.csv
2025-04-18 15:17:19,088 - INFO - Using Trainer.fit with dataset preprocessing from TTS.bin.train_tts
2025-04-18 15:17:19,091 - WARNING - Trainer.fit with preprocessing failed: 'dict' object has no attribute 'meta_file_attn_mask'
Traceback (most recent call last):
  File "D:\Scripts\EchoPersona\train_tts_model.py", line 315, in train_model
    train_samples, eval_samples = load_tts_samples(
                                  ^^^^^^^^^^^^^^^^^
  File "D:\Scripts\EchoPersona\.venv\Lib\site-packages\TTS\tts\datasets\__init__.py", line 137, in load_tts_samples
    if dataset.meta_file_attn_mask:
       ^^^^^^^^^^^^^^^^^^^^^^^^^^^
AttributeError: 'dict' object has no attribute 'meta_file_attn_mask'

2025-04-18 15:17:19,091 - INFO - Attempting manual dataset handling with Trainer.fit
2025-04-18 15:17:19,092 - INFO - Loaded configuration from voice_datasets\Zhongli\zhongli_config.json
2025-04-18 15:17:19,096 - ERROR - Manual dataset handling failed: 'dict' object has no attribute 'parse_known_args'
Traceback (most recent call last):
  File "D:\Scripts\EchoPersona\train_tts_model.py", line 315, in train_model
    train_samples, eval_samples = load_tts_samples(
                                  ^^^^^^^^^^^^^^^^^
  File "D:\Scripts\EchoPersona\.venv\Lib\site-packages\TTS\tts\datasets\__init__.py", line 137, in load_tts_samples
    if dataset.meta_file_attn_mask:
       ^^^^^^^^^^^^^^^^^^^^^^^^^^^
AttributeError: 'dict' object has no attribute 'meta_file_attn_mask'

During handling of the above exception, another exception occurred:

Traceback (most recent call last):
  File "D:\Scripts\EchoPersona\train_tts_model.py", line 371, in train_model
    trainer = Trainer(
              ^^^^^^^^
  File "D:\Scripts\EchoPersona\.venv\Lib\site-packages\trainer\trainer.py", line 400, in __init__
    config, new_fields = self.init_training(args, coqpit_overrides, config)
                         ^^^^^^^^^^^^^^^^^^^^^^^^^^^^^^^^^^^^^^^^^^^^^^^^^^
  File "D:\Scripts\EchoPersona\.venv\Lib\site-packages\trainer\trainer.py", line 745, in init_training
    config.parse_known_args(coqpit_overrides, relaxed_parser=True)
    ^^^^^^^^^^^^^^^^^^^^^^^
AttributeError: 'dict' object has no attribute 'parse_known_args'

2025-04-18 15:17:19,098 - ERROR - Training failed: All Trainer.fit attempts failed
Traceback (most recent call last):
  File "D:\Scripts\EchoPersona\train_tts_model.py", line 315, in train_model
    train_samples, eval_samples = load_tts_samples(
                                  ^^^^^^^^^^^^^^^^^
  File "D:\Scripts\EchoPersona\.venv\Lib\site-packages\TTS\tts\datasets\__init__.py", line 137, in load_tts_samples
    if dataset.meta_file_attn_mask:
       ^^^^^^^^^^^^^^^^^^^^^^^^^^^
AttributeError: 'dict' object has no attribute 'meta_file_attn_mask'

During handling of the above exception, another exception occurred:

Traceback (most recent call last):
  File "D:\Scripts\EchoPersona\train_tts_model.py", line 371, in train_model
    trainer = Trainer(
              ^^^^^^^^
  File "D:\Scripts\EchoPersona\.venv\Lib\site-packages\trainer\trainer.py", line 400, in __init__
    config, new_fields = self.init_training(args, coqpit_overrides, config)
                         ^^^^^^^^^^^^^^^^^^^^^^^^^^^^^^^^^^^^^^^^^^^^^^^^^^
  File "D:\Scripts\EchoPersona\.venv\Lib\site-packages\trainer\trainer.py", line 745, in init_training
    config.parse_known_args(coqpit_overrides, relaxed_parser=True)
    ^^^^^^^^^^^^^^^^^^^^^^^
AttributeError: 'dict' object has no attribute 'parse_known_args'

During handling of the above exception, another exception occurred:

Traceback (most recent call last):
  File "D:\Scripts\EchoPersona\train_tts_model.py", line 390, in train_model
    raise RuntimeError("All Trainer.fit attempts failed")
RuntimeError: All Trainer.fit attempts failed

2025-04-18 15:19:25,308 - INFO - Successfully imported Trainer, TrainerArgs, load_tts_samples, setup_model from TTS.bin.train_tts
2025-04-18 15:19:30,502 - INFO - Found config for Zhongli: voice_datasets\Zhongli\zhongli_config.json
2025-04-18 15:19:30,503 - INFO - Found 1 character configs in voice_datasets
2025-04-18 15:19:40,229 - INFO - Loaded configuration from voice_datasets\Zhongli\zhongli_config.json
2025-04-18 15:19:40,231 - INFO - Loaded configuration from voice_datasets\Zhongli\zhongli_config.json
2025-04-18 15:19:40,232 - INFO - Model tts_models/en/ek1/tacotron2 not found in cache. Attempting to download.
2025-04-18 15:19:40,245 - INFO - Successfully downloaded model: tts_models/en/ek1/tacotron2 to C:\Users\DRAGOHN/.cache/tts/tts_models--en--ek1--tacotron2
2025-04-18 15:19:40,245 - INFO - Using CPU for training.
2025-04-18 15:19:40,247 - INFO - Using training metadata file at: voice_datasets\Zhongli\metadata.csv
2025-04-18 15:19:40,247 - INFO - Using validation metadata file at: voice_datasets\Zhongli\valid.csv
2025-04-18 15:19:40,247 - INFO - Using Trainer.fit with dataset preprocessing from TTS.bin.train_tts
2025-04-18 15:19:40,248 - WARNING - Trainer.fit with preprocessing failed: 'types.SimpleNamespace' object is not subscriptable
Traceback (most recent call last):
  File "D:\Scripts\EchoPersona\train_tts_model.py", line 326, in train_model
    train_samples, eval_samples = load_tts_samples(
                                  ^^^^^^^^^^^^^^^^^
  File "D:\Scripts\EchoPersona\.venv\Lib\site-packages\TTS\tts\datasets\__init__.py", line 108, in load_tts_samples
    formatter_name = dataset["formatter"]
                     ~~~~~~~^^^^^^^^^^^^^
TypeError: 'types.SimpleNamespace' object is not subscriptable

2025-04-18 15:19:40,249 - INFO - Attempting manual dataset handling with Trainer.fit
2025-04-18 15:19:40,249 - INFO - Loaded configuration from voice_datasets\Zhongli\zhongli_config.json
2025-04-18 15:19:40,253 - ERROR - Manual dataset handling failed: 'dict' object has no attribute 'parse_known_args'
Traceback (most recent call last):
  File "D:\Scripts\EchoPersona\train_tts_model.py", line 326, in train_model
    train_samples, eval_samples = load_tts_samples(
                                  ^^^^^^^^^^^^^^^^^
  File "D:\Scripts\EchoPersona\.venv\Lib\site-packages\TTS\tts\datasets\__init__.py", line 108, in load_tts_samples
    formatter_name = dataset["formatter"]
                     ~~~~~~~^^^^^^^^^^^^^
TypeError: 'types.SimpleNamespace' object is not subscriptable

During handling of the above exception, another exception occurred:

Traceback (most recent call last):
  File "D:\Scripts\EchoPersona\train_tts_model.py", line 371, in train_model
    trainer = Trainer(
              ^^^^^^^^
  File "D:\Scripts\EchoPersona\.venv\Lib\site-packages\trainer\trainer.py", line 400, in __init__
    config, new_fields = self.init_training(args, coqpit_overrides, config)
                         ^^^^^^^^^^^^^^^^^^^^^^^^^^^^^^^^^^^^^^^^^^^^^^^^^^
  File "D:\Scripts\EchoPersona\.venv\Lib\site-packages\trainer\trainer.py", line 745, in init_training
    config.parse_known_args(coqpit_overrides, relaxed_parser=True)
    ^^^^^^^^^^^^^^^^^^^^^^^
AttributeError: 'dict' object has no attribute 'parse_known_args'

2025-04-18 15:19:40,255 - ERROR - Training failed: All Trainer.fit attempts failed
Traceback (most recent call last):
  File "D:\Scripts\EchoPersona\train_tts_model.py", line 326, in train_model
    train_samples, eval_samples = load_tts_samples(
                                  ^^^^^^^^^^^^^^^^^
  File "D:\Scripts\EchoPersona\.venv\Lib\site-packages\TTS\tts\datasets\__init__.py", line 108, in load_tts_samples
    formatter_name = dataset["formatter"]
                     ~~~~~~~^^^^^^^^^^^^^
TypeError: 'types.SimpleNamespace' object is not subscriptable

During handling of the above exception, another exception occurred:

Traceback (most recent call last):
  File "D:\Scripts\EchoPersona\train_tts_model.py", line 371, in train_model
    trainer = Trainer(
              ^^^^^^^^
  File "D:\Scripts\EchoPersona\.venv\Lib\site-packages\trainer\trainer.py", line 400, in __init__
    config, new_fields = self.init_training(args, coqpit_overrides, config)
                         ^^^^^^^^^^^^^^^^^^^^^^^^^^^^^^^^^^^^^^^^^^^^^^^^^^
  File "D:\Scripts\EchoPersona\.venv\Lib\site-packages\trainer\trainer.py", line 745, in init_training
    config.parse_known_args(coqpit_overrides, relaxed_parser=True)
    ^^^^^^^^^^^^^^^^^^^^^^^
AttributeError: 'dict' object has no attribute 'parse_known_args'

During handling of the above exception, another exception occurred:

Traceback (most recent call last):
  File "D:\Scripts\EchoPersona\train_tts_model.py", line 390, in train_model
    raise RuntimeError("All Trainer.fit attempts failed")
RuntimeError: All Trainer.fit attempts failed

2025-04-18 15:20:47,493 - INFO - Successfully imported Trainer, TrainerArgs, load_tts_samples, setup_model from TTS.bin.train_tts
2025-04-18 15:20:53,069 - INFO - Found config for Zhongli: voice_datasets\Zhongli\zhongli_config.json
2025-04-18 15:20:53,069 - INFO - Found 1 character configs in voice_datasets
2025-04-18 15:20:57,029 - INFO - Loaded configuration from voice_datasets\Zhongli\zhongli_config.json
2025-04-18 15:20:57,032 - INFO - Loaded configuration from voice_datasets\Zhongli\zhongli_config.json
2025-04-18 15:20:57,033 - INFO - Model tts_models/en/ek1/tacotron2 not found in cache. Attempting to download.
2025-04-18 15:20:57,046 - INFO - Successfully downloaded model: tts_models/en/ek1/tacotron2 to C:\Users\DRAGOHN/.cache/tts/tts_models--en--ek1--tacotron2
2025-04-18 15:20:57,047 - INFO - Using CPU for training.
2025-04-18 15:20:57,049 - INFO - Using training metadata file at: voice_datasets\Zhongli\metadata.csv
2025-04-18 15:20:57,049 - INFO - Using validation metadata file at: voice_datasets\Zhongli\valid.csv
2025-04-18 15:20:57,049 - INFO - Using Trainer.fit with dataset preprocessing from TTS.bin.train_tts
2025-04-18 15:20:57,052 - WARNING - Trainer.fit with preprocessing failed: 'dict' object has no attribute 'meta_file_attn_mask'
Traceback (most recent call last):
  File "D:\Scripts\EchoPersona\train_tts_model.py", line 326, in train_model
    train_samples, eval_samples = load_tts_samples(
                                  ^^^^^^^^^^^^^^^^^
  File "D:\Scripts\EchoPersona\.venv\Lib\site-packages\TTS\tts\datasets\__init__.py", line 137, in load_tts_samples
    if dataset.meta_file_attn_mask:
       ^^^^^^^^^^^^^^^^^^^^^^^^^^^
AttributeError: 'dict' object has no attribute 'meta_file_attn_mask'

2025-04-18 15:20:57,053 - INFO - Attempting manual dataset handling with Trainer.fit
2025-04-18 15:20:57,053 - INFO - Loaded configuration from voice_datasets\Zhongli\zhongli_config.json
2025-04-18 15:20:57,057 - ERROR - Manual dataset handling failed: 'dict' object has no attribute 'parse_known_args'
Traceback (most recent call last):
  File "D:\Scripts\EchoPersona\train_tts_model.py", line 326, in train_model
    train_samples, eval_samples = load_tts_samples(
                                  ^^^^^^^^^^^^^^^^^
  File "D:\Scripts\EchoPersona\.venv\Lib\site-packages\TTS\tts\datasets\__init__.py", line 137, in load_tts_samples
    if dataset.meta_file_attn_mask:
       ^^^^^^^^^^^^^^^^^^^^^^^^^^^
AttributeError: 'dict' object has no attribute 'meta_file_attn_mask'

During handling of the above exception, another exception occurred:

Traceback (most recent call last):
  File "D:\Scripts\EchoPersona\train_tts_model.py", line 371, in train_model
    trainer = Trainer(
              ^^^^^^^^
  File "D:\Scripts\EchoPersona\.venv\Lib\site-packages\trainer\trainer.py", line 400, in __init__
    config, new_fields = self.init_training(args, coqpit_overrides, config)
                         ^^^^^^^^^^^^^^^^^^^^^^^^^^^^^^^^^^^^^^^^^^^^^^^^^^
  File "D:\Scripts\EchoPersona\.venv\Lib\site-packages\trainer\trainer.py", line 745, in init_training
    config.parse_known_args(coqpit_overrides, relaxed_parser=True)
    ^^^^^^^^^^^^^^^^^^^^^^^
AttributeError: 'dict' object has no attribute 'parse_known_args'

2025-04-18 15:20:57,060 - ERROR - Training failed: All Trainer.fit attempts failed
Traceback (most recent call last):
  File "D:\Scripts\EchoPersona\train_tts_model.py", line 326, in train_model
    train_samples, eval_samples = load_tts_samples(
                                  ^^^^^^^^^^^^^^^^^
  File "D:\Scripts\EchoPersona\.venv\Lib\site-packages\TTS\tts\datasets\__init__.py", line 137, in load_tts_samples
    if dataset.meta_file_attn_mask:
       ^^^^^^^^^^^^^^^^^^^^^^^^^^^
AttributeError: 'dict' object has no attribute 'meta_file_attn_mask'

During handling of the above exception, another exception occurred:

Traceback (most recent call last):
  File "D:\Scripts\EchoPersona\train_tts_model.py", line 371, in train_model
    trainer = Trainer(
              ^^^^^^^^
  File "D:\Scripts\EchoPersona\.venv\Lib\site-packages\trainer\trainer.py", line 400, in __init__
    config, new_fields = self.init_training(args, coqpit_overrides, config)
                         ^^^^^^^^^^^^^^^^^^^^^^^^^^^^^^^^^^^^^^^^^^^^^^^^^^
  File "D:\Scripts\EchoPersona\.venv\Lib\site-packages\trainer\trainer.py", line 745, in init_training
    config.parse_known_args(coqpit_overrides, relaxed_parser=True)
    ^^^^^^^^^^^^^^^^^^^^^^^
AttributeError: 'dict' object has no attribute 'parse_known_args'

During handling of the above exception, another exception occurred:

Traceback (most recent call last):
  File "D:\Scripts\EchoPersona\train_tts_model.py", line 390, in train_model
    raise RuntimeError("All Trainer.fit attempts failed")
RuntimeError: All Trainer.fit attempts failed

2025-04-18 15:22:28,534 - INFO - Successfully imported Trainer, TrainerArgs, load_tts_samples, setup_model from TTS.bin.train_tts
2025-04-18 15:22:34,198 - INFO - Found config for Zhongli: voice_datasets\Zhongli\zhongli_config.json
2025-04-18 15:22:34,198 - INFO - Found 1 character configs in voice_datasets
2025-04-18 15:22:38,462 - INFO - Loaded configuration from voice_datasets\Zhongli\zhongli_config.json
2025-04-18 15:22:38,464 - INFO - Loaded configuration from voice_datasets\Zhongli\zhongli_config.json
2025-04-18 15:22:38,465 - INFO - Model tts_models/en/ek1/tacotron2 not found in cache. Attempting to download.
2025-04-18 15:22:38,478 - INFO - Successfully downloaded model: tts_models/en/ek1/tacotron2 to C:\Users\DRAGOHN/.cache/tts/tts_models--en--ek1--tacotron2
2025-04-18 15:22:38,478 - INFO - Using CPU for training.
2025-04-18 15:22:38,480 - INFO - Using training metadata file at: voice_datasets\Zhongli\metadata.csv
2025-04-18 15:22:38,480 - INFO - Using validation metadata file at: voice_datasets\Zhongli\valid.csv
2025-04-18 15:22:38,480 - INFO - Using Trainer.fit with dataset preprocessing from TTS.bin.train_tts
2025-04-18 15:22:38,483 - WARNING - Trainer.fit with preprocessing failed: 'dict' object has no attribute 'meta_file_attn_mask'
Traceback (most recent call last):
  File "D:\Scripts\EchoPersona\train_tts_model.py", line 326, in train_model
    train_samples, eval_samples = load_tts_samples(
                                  ^^^^^^^^^^^^^^^^^
  File "D:\Scripts\EchoPersona\.venv\Lib\site-packages\TTS\tts\datasets\__init__.py", line 137, in load_tts_samples
    if dataset.meta_file_attn_mask:
       ^^^^^^^^^^^^^^^^^^^^^^^^^^^
AttributeError: 'dict' object has no attribute 'meta_file_attn_mask'

2025-04-18 15:22:38,483 - INFO - Attempting manual dataset handling with Trainer.fit
2025-04-18 15:22:38,484 - INFO - Loaded configuration from voice_datasets\Zhongli\zhongli_config.json
2025-04-18 15:22:38,488 - ERROR - Manual dataset handling failed: 'dict' object has no attribute 'parse_known_args'
Traceback (most recent call last):
  File "D:\Scripts\EchoPersona\train_tts_model.py", line 326, in train_model
    train_samples, eval_samples = load_tts_samples(
                                  ^^^^^^^^^^^^^^^^^
  File "D:\Scripts\EchoPersona\.venv\Lib\site-packages\TTS\tts\datasets\__init__.py", line 137, in load_tts_samples
    if dataset.meta_file_attn_mask:
       ^^^^^^^^^^^^^^^^^^^^^^^^^^^
AttributeError: 'dict' object has no attribute 'meta_file_attn_mask'

During handling of the above exception, another exception occurred:

Traceback (most recent call last):
  File "D:\Scripts\EchoPersona\train_tts_model.py", line 371, in train_model
    trainer = Trainer(
              ^^^^^^^^
  File "D:\Scripts\EchoPersona\.venv\Lib\site-packages\trainer\trainer.py", line 400, in __init__
    config, new_fields = self.init_training(args, coqpit_overrides, config)
                         ^^^^^^^^^^^^^^^^^^^^^^^^^^^^^^^^^^^^^^^^^^^^^^^^^^
  File "D:\Scripts\EchoPersona\.venv\Lib\site-packages\trainer\trainer.py", line 745, in init_training
    config.parse_known_args(coqpit_overrides, relaxed_parser=True)
    ^^^^^^^^^^^^^^^^^^^^^^^
AttributeError: 'dict' object has no attribute 'parse_known_args'

2025-04-18 15:22:38,493 - ERROR - Training failed: All Trainer.fit attempts failed
Traceback (most recent call last):
  File "D:\Scripts\EchoPersona\train_tts_model.py", line 326, in train_model
    train_samples, eval_samples = load_tts_samples(
                                  ^^^^^^^^^^^^^^^^^
  File "D:\Scripts\EchoPersona\.venv\Lib\site-packages\TTS\tts\datasets\__init__.py", line 137, in load_tts_samples
    if dataset.meta_file_attn_mask:
       ^^^^^^^^^^^^^^^^^^^^^^^^^^^
AttributeError: 'dict' object has no attribute 'meta_file_attn_mask'

During handling of the above exception, another exception occurred:

Traceback (most recent call last):
  File "D:\Scripts\EchoPersona\train_tts_model.py", line 371, in train_model
    trainer = Trainer(
              ^^^^^^^^
  File "D:\Scripts\EchoPersona\.venv\Lib\site-packages\trainer\trainer.py", line 400, in __init__
    config, new_fields = self.init_training(args, coqpit_overrides, config)
                         ^^^^^^^^^^^^^^^^^^^^^^^^^^^^^^^^^^^^^^^^^^^^^^^^^^
  File "D:\Scripts\EchoPersona\.venv\Lib\site-packages\trainer\trainer.py", line 745, in init_training
    config.parse_known_args(coqpit_overrides, relaxed_parser=True)
    ^^^^^^^^^^^^^^^^^^^^^^^
AttributeError: 'dict' object has no attribute 'parse_known_args'

During handling of the above exception, another exception occurred:

Traceback (most recent call last):
  File "D:\Scripts\EchoPersona\train_tts_model.py", line 390, in train_model
    raise RuntimeError("All Trainer.fit attempts failed")
RuntimeError: All Trainer.fit attempts failed

2025-04-18 15:25:49,977 - INFO - Successfully imported Trainer, TrainerArgs, load_tts_samples, setup_model from TTS.bin.train_tts
2025-04-18 15:25:55,552 - INFO - Found config for Zhongli: voice_datasets\Zhongli\zhongli_config.json
2025-04-18 15:25:55,552 - INFO - Found 1 character configs in voice_datasets
2025-04-18 15:26:02,299 - INFO - Loaded configuration from voice_datasets\Zhongli\zhongli_config.json
2025-04-18 15:26:02,300 - INFO - Loaded configuration from voice_datasets\Zhongli\zhongli_config.json
2025-04-18 15:26:02,301 - INFO - Model tts_models/en/ek1/tacotron2 not found in cache. Attempting to download.
2025-04-18 15:26:02,314 - INFO - Successfully downloaded model: tts_models/en/ek1/tacotron2 to C:\Users\DRAGOHN/.cache/tts/tts_models--en--ek1--tacotron2
2025-04-18 15:26:02,314 - INFO - Using CPU for training.
2025-04-18 15:26:02,316 - INFO - Using training metadata file at: voice_datasets\Zhongli\metadata.csv
2025-04-18 15:26:02,316 - INFO - Using validation metadata file at: voice_datasets\Zhongli\valid.csv
2025-04-18 15:26:02,317 - INFO - Using Trainer.fit with dataset preprocessing from TTS.bin.train_tts
2025-04-18 15:26:02,317 - WARNING - Trainer.fit with preprocessing failed: 'types.SimpleNamespace' object is not subscriptable
Traceback (most recent call last):
  File "D:\Scripts\EchoPersona\train_tts_model.py", line 328, in train_model
    train_samples, eval_samples = load_tts_samples(
                                  ^^^^^^^^^^^^^^^^^
  File "D:\Scripts\EchoPersona\.venv\Lib\site-packages\TTS\tts\datasets\__init__.py", line 108, in load_tts_samples
    formatter_name = dataset["formatter"]
                     ~~~~~~~^^^^^^^^^^^^^
TypeError: 'types.SimpleNamespace' object is not subscriptable

2025-04-18 15:26:02,318 - INFO - Attempting manual dataset handling with Trainer.fit
2025-04-18 15:26:02,321 - ERROR - Manual dataset handling failed: 'dict' object has no attribute 'parse_known_args'
Traceback (most recent call last):
  File "D:\Scripts\EchoPersona\train_tts_model.py", line 328, in train_model
    train_samples, eval_samples = load_tts_samples(
                                  ^^^^^^^^^^^^^^^^^
  File "D:\Scripts\EchoPersona\.venv\Lib\site-packages\TTS\tts\datasets\__init__.py", line 108, in load_tts_samples
    formatter_name = dataset["formatter"]
                     ~~~~~~~^^^^^^^^^^^^^
TypeError: 'types.SimpleNamespace' object is not subscriptable

During handling of the above exception, another exception occurred:

Traceback (most recent call last):
  File "D:\Scripts\EchoPersona\train_tts_model.py", line 373, in train_model
    trainer = Trainer(
              ^^^^^^^^
  File "D:\Scripts\EchoPersona\.venv\Lib\site-packages\trainer\trainer.py", line 400, in __init__
    config, new_fields = self.init_training(args, coqpit_overrides, config)
                         ^^^^^^^^^^^^^^^^^^^^^^^^^^^^^^^^^^^^^^^^^^^^^^^^^^
  File "D:\Scripts\EchoPersona\.venv\Lib\site-packages\trainer\trainer.py", line 745, in init_training
    config.parse_known_args(coqpit_overrides, relaxed_parser=True)
    ^^^^^^^^^^^^^^^^^^^^^^^
AttributeError: 'dict' object has no attribute 'parse_known_args'

2025-04-18 15:26:02,323 - ERROR - Training failed: All Trainer.fit attempts failed
Traceback (most recent call last):
  File "D:\Scripts\EchoPersona\train_tts_model.py", line 328, in train_model
    train_samples, eval_samples = load_tts_samples(
                                  ^^^^^^^^^^^^^^^^^
  File "D:\Scripts\EchoPersona\.venv\Lib\site-packages\TTS\tts\datasets\__init__.py", line 108, in load_tts_samples
    formatter_name = dataset["formatter"]
                     ~~~~~~~^^^^^^^^^^^^^
TypeError: 'types.SimpleNamespace' object is not subscriptable

During handling of the above exception, another exception occurred:

Traceback (most recent call last):
  File "D:\Scripts\EchoPersona\train_tts_model.py", line 373, in train_model
    trainer = Trainer(
              ^^^^^^^^
  File "D:\Scripts\EchoPersona\.venv\Lib\site-packages\trainer\trainer.py", line 400, in __init__
    config, new_fields = self.init_training(args, coqpit_overrides, config)
                         ^^^^^^^^^^^^^^^^^^^^^^^^^^^^^^^^^^^^^^^^^^^^^^^^^^
  File "D:\Scripts\EchoPersona\.venv\Lib\site-packages\trainer\trainer.py", line 745, in init_training
    config.parse_known_args(coqpit_overrides, relaxed_parser=True)
    ^^^^^^^^^^^^^^^^^^^^^^^
AttributeError: 'dict' object has no attribute 'parse_known_args'

During handling of the above exception, another exception occurred:

Traceback (most recent call last):
  File "D:\Scripts\EchoPersona\train_tts_model.py", line 392, in train_model
    raise RuntimeError("All Trainer.fit attempts failed")
RuntimeError: All Trainer.fit attempts failed

2025-04-18 15:32:23,667 - INFO - Successfully imported Trainer, TrainerArgs, load_tts_samples, setup_model from TTS.bin.train_tts
2025-04-18 15:32:28,849 - INFO - Found config for Zhongli: voice_datasets\Zhongli\zhongli_config.json
2025-04-18 15:32:28,850 - INFO - Found 1 character configs in voice_datasets
2025-04-18 15:32:28,850 - INFO - Loaded configuration from voice_datasets\Zhongli\zhongli_config.json
2025-04-18 15:32:28,851 - INFO - Training model for Zhongli...
2025-04-18 15:32:28,851 - INFO - Loaded configuration from voice_datasets\Zhongli\zhongli_config.json
2025-04-18 15:32:28,852 - INFO - Model tts_models/en/ek1/tacotron2 not found in cache. Attempting to download.
2025-04-18 15:32:28,871 - INFO - Successfully downloaded model: tts_models/en/ek1/tacotron2 to C:\Users\DRAGOHN/.cache/tts/tts_models--en--ek1--tacotron2
2025-04-18 15:32:28,871 - INFO - Using CPU for training.
2025-04-18 15:32:28,873 - INFO - Using training metadata file at: voice_datasets\Zhongli\metadata.csv
2025-04-18 15:32:28,874 - INFO - Using validation metadata file at: voice_datasets\Zhongli\valid.csv
2025-04-18 15:32:28,874 - INFO - Using Trainer.fit with dataset preprocessing from TTS.bin.train_tts
2025-04-18 15:32:28,877 - WARNING - Trainer.fit with preprocessing failed: 'dict' object has no attribute 'meta_file_attn_mask'
Traceback (most recent call last):
  File "D:\Scripts\EchoPersona\train_tts_model.py", line 327, in train_model
    train_samples, eval_samples = load_tts_samples(
                                  ^^^^^^^^^^^^^^^^^
  File "D:\Scripts\EchoPersona\.venv\Lib\site-packages\TTS\tts\datasets\__init__.py", line 137, in load_tts_samples
    if dataset.meta_file_attn_mask:
       ^^^^^^^^^^^^^^^^^^^^^^^^^^^
AttributeError: 'dict' object has no attribute 'meta_file_attn_mask'

2025-04-18 15:32:28,878 - INFO - Attempting manual dataset handling with Trainer.fit
2025-04-18 15:32:28,882 - ERROR - Manual dataset handling failed: 'dict' object has no attribute 'parse_known_args'
Traceback (most recent call last):
  File "D:\Scripts\EchoPersona\train_tts_model.py", line 327, in train_model
    train_samples, eval_samples = load_tts_samples(
                                  ^^^^^^^^^^^^^^^^^
  File "D:\Scripts\EchoPersona\.venv\Lib\site-packages\TTS\tts\datasets\__init__.py", line 137, in load_tts_samples
    if dataset.meta_file_attn_mask:
       ^^^^^^^^^^^^^^^^^^^^^^^^^^^
AttributeError: 'dict' object has no attribute 'meta_file_attn_mask'

During handling of the above exception, another exception occurred:

Traceback (most recent call last):
  File "D:\Scripts\EchoPersona\train_tts_model.py", line 372, in train_model
    trainer = Trainer(
              ^^^^^^^^
  File "D:\Scripts\EchoPersona\.venv\Lib\site-packages\trainer\trainer.py", line 400, in __init__
    config, new_fields = self.init_training(args, coqpit_overrides, config)
                         ^^^^^^^^^^^^^^^^^^^^^^^^^^^^^^^^^^^^^^^^^^^^^^^^^^
  File "D:\Scripts\EchoPersona\.venv\Lib\site-packages\trainer\trainer.py", line 745, in init_training
    config.parse_known_args(coqpit_overrides, relaxed_parser=True)
    ^^^^^^^^^^^^^^^^^^^^^^^
AttributeError: 'dict' object has no attribute 'parse_known_args'

2025-04-18 15:32:28,884 - ERROR - Training failed: All Trainer.fit attempts failed
Traceback (most recent call last):
  File "D:\Scripts\EchoPersona\train_tts_model.py", line 327, in train_model
    train_samples, eval_samples = load_tts_samples(
                                  ^^^^^^^^^^^^^^^^^
  File "D:\Scripts\EchoPersona\.venv\Lib\site-packages\TTS\tts\datasets\__init__.py", line 137, in load_tts_samples
    if dataset.meta_file_attn_mask:
       ^^^^^^^^^^^^^^^^^^^^^^^^^^^
AttributeError: 'dict' object has no attribute 'meta_file_attn_mask'

During handling of the above exception, another exception occurred:

Traceback (most recent call last):
  File "D:\Scripts\EchoPersona\train_tts_model.py", line 372, in train_model
    trainer = Trainer(
              ^^^^^^^^
  File "D:\Scripts\EchoPersona\.venv\Lib\site-packages\trainer\trainer.py", line 400, in __init__
    config, new_fields = self.init_training(args, coqpit_overrides, config)
                         ^^^^^^^^^^^^^^^^^^^^^^^^^^^^^^^^^^^^^^^^^^^^^^^^^^
  File "D:\Scripts\EchoPersona\.venv\Lib\site-packages\trainer\trainer.py", line 745, in init_training
    config.parse_known_args(coqpit_overrides, relaxed_parser=True)
    ^^^^^^^^^^^^^^^^^^^^^^^
AttributeError: 'dict' object has no attribute 'parse_known_args'

During handling of the above exception, another exception occurred:

Traceback (most recent call last):
  File "D:\Scripts\EchoPersona\train_tts_model.py", line 391, in train_model
    raise RuntimeError("All Trainer.fit attempts failed")
RuntimeError: All Trainer.fit attempts failed

2025-04-18 15:32:28,885 - ERROR - Failed to process Zhongli: All Trainer.fit attempts failed
2025-04-18 15:38:46,614 - INFO - Successfully imported Trainer, TrainerArgs, load_tts_samples, setup_model from TTS.bin.train_tts
2025-04-18 15:38:51,710 - INFO - Found config for Zhongli: voice_datasets\Zhongli\zhongli_config.json
2025-04-18 15:38:51,710 - INFO - Found 1 character configs in voice_datasets
2025-04-18 15:38:51,711 - INFO - Loaded configuration from voice_datasets\Zhongli\zhongli_config.json
2025-04-18 15:38:51,711 - INFO - Training model for Zhongli...
2025-04-18 15:38:51,712 - INFO - Loaded configuration from voice_datasets\Zhongli\zhongli_config.json
2025-04-18 15:38:51,713 - INFO - Model tts_models/en/ek1/tacotron2 not found in cache. Attempting to download.
2025-04-18 15:38:51,733 - INFO - Successfully downloaded model: tts_models/en/ek1/tacotron2 to C:\Users\DRAGOHN/.cache/tts/tts_models--en--ek1--tacotron2
2025-04-18 15:38:51,733 - INFO - Using CPU for training.
2025-04-18 15:38:51,735 - INFO - Using training metadata file at: voice_datasets\Zhongli\metadata.csv
2025-04-18 15:38:51,736 - INFO - Using validation metadata file at: voice_datasets\Zhongli\valid.csv
2025-04-18 15:38:51,736 - ERROR - Training failed: Coqpit.__init__() got an unexpected keyword argument 'output_path'
Traceback (most recent call last):
  File "D:\Scripts\EchoPersona\train_tts_model.py", line 282, in train_model
    config = Coqpit(**config)  # Convert dictionary to Coqpit object
             ^^^^^^^^^^^^^^^^
TypeError: Coqpit.__init__() got an unexpected keyword argument 'output_path'

2025-04-18 15:38:51,737 - ERROR - Failed to process Zhongli: Coqpit.__init__() got an unexpected keyword argument 'output_path'
2025-04-18 15:40:09,105 - INFO - Successfully imported Trainer, TrainerArgs, load_tts_samples, setup_model from TTS.bin.train_tts
2025-04-18 15:40:14,166 - INFO - Found config for Zhongli: voice_datasets\Zhongli\zhongli_config.json
2025-04-18 15:40:14,166 - INFO - Found 1 character configs in voice_datasets
2025-04-18 15:40:14,166 - INFO - Loaded configuration from voice_datasets\Zhongli\zhongli_config.json
2025-04-18 15:40:14,167 - INFO - Training model for Zhongli...
2025-04-18 15:40:14,167 - INFO - Loaded configuration from voice_datasets\Zhongli\zhongli_config.json
2025-04-18 15:40:14,168 - INFO - Model tts_models/en/ek1/tacotron2 not found in cache. Attempting to download.
2025-04-18 15:40:14,186 - INFO - Successfully downloaded model: tts_models/en/ek1/tacotron2 to C:\Users\DRAGOHN/.cache/tts/tts_models--en--ek1--tacotron2
2025-04-18 15:40:14,187 - INFO - Using CPU for training.
2025-04-18 15:40:14,189 - INFO - Using training metadata file at: voice_datasets\Zhongli\metadata.csv
2025-04-18 15:40:14,190 - INFO - Using validation metadata file at: voice_datasets\Zhongli\valid.csv
2025-04-18 15:40:14,190 - INFO - Using Trainer.fit with dataset preprocessing from TTS.bin.train_tts
2025-04-18 15:40:14,192 - WARNING - Trainer.fit with preprocessing failed: 'dict' object has no attribute 'meta_file_attn_mask'
Traceback (most recent call last):
  File "D:\Scripts\EchoPersona\train_tts_model.py", line 308, in train_model
    train_samples, eval_samples = load_tts_samples(
                                  ^^^^^^^^^^^^^^^^^
  File "D:\Scripts\EchoPersona\.venv\Lib\site-packages\TTS\tts\datasets\__init__.py", line 137, in load_tts_samples
    if dataset.meta_file_attn_mask:
       ^^^^^^^^^^^^^^^^^^^^^^^^^^^
AttributeError: 'dict' object has no attribute 'meta_file_attn_mask'

2025-04-18 15:40:14,193 - INFO - Attempting manual dataset handling with Trainer.fit
2025-04-18 15:40:14,389 - ERROR - Manual dataset handling failed: 'Coqpit' object has no attribute 'output_path'
Traceback (most recent call last):
  File "D:\Scripts\EchoPersona\train_tts_model.py", line 308, in train_model
    train_samples, eval_samples = load_tts_samples(
                                  ^^^^^^^^^^^^^^^^^
  File "D:\Scripts\EchoPersona\.venv\Lib\site-packages\TTS\tts\datasets\__init__.py", line 137, in load_tts_samples
    if dataset.meta_file_attn_mask:
       ^^^^^^^^^^^^^^^^^^^^^^^^^^^
AttributeError: 'dict' object has no attribute 'meta_file_attn_mask'

During handling of the above exception, another exception occurred:

Traceback (most recent call last):
  File "D:\Scripts\EchoPersona\train_tts_model.py", line 355, in train_model
    trainer = Trainer(
              ^^^^^^^^
  File "D:\Scripts\EchoPersona\.venv\Lib\site-packages\trainer\trainer.py", line 414, in __init__
    output_path = get_experiment_folder_path(config.output_path, config.run_name)
                                             ^^^^^^^^^^^^^^^^^^
  File "D:\Scripts\EchoPersona\.venv\Lib\site-packages\coqpit\coqpit.py", line 626, in __getattribute__
    value = super().__getattribute__(arg)
            ^^^^^^^^^^^^^^^^^^^^^^^^^^^^^
AttributeError: 'Coqpit' object has no attribute 'output_path'

2025-04-18 15:40:14,391 - ERROR - Training failed: All Trainer.fit attempts failed
Traceback (most recent call last):
  File "D:\Scripts\EchoPersona\train_tts_model.py", line 308, in train_model
    train_samples, eval_samples = load_tts_samples(
                                  ^^^^^^^^^^^^^^^^^
  File "D:\Scripts\EchoPersona\.venv\Lib\site-packages\TTS\tts\datasets\__init__.py", line 137, in load_tts_samples
    if dataset.meta_file_attn_mask:
       ^^^^^^^^^^^^^^^^^^^^^^^^^^^
AttributeError: 'dict' object has no attribute 'meta_file_attn_mask'

During handling of the above exception, another exception occurred:

Traceback (most recent call last):
  File "D:\Scripts\EchoPersona\train_tts_model.py", line 355, in train_model
    trainer = Trainer(
              ^^^^^^^^
  File "D:\Scripts\EchoPersona\.venv\Lib\site-packages\trainer\trainer.py", line 414, in __init__
    output_path = get_experiment_folder_path(config.output_path, config.run_name)
                                             ^^^^^^^^^^^^^^^^^^
  File "D:\Scripts\EchoPersona\.venv\Lib\site-packages\coqpit\coqpit.py", line 626, in __getattribute__
    value = super().__getattribute__(arg)
            ^^^^^^^^^^^^^^^^^^^^^^^^^^^^^
AttributeError: 'Coqpit' object has no attribute 'output_path'

During handling of the above exception, another exception occurred:

Traceback (most recent call last):
  File "D:\Scripts\EchoPersona\train_tts_model.py", line 374, in train_model
    raise RuntimeError("All Trainer.fit attempts failed")
RuntimeError: All Trainer.fit attempts failed

2025-04-18 15:40:14,393 - ERROR - Failed to process Zhongli: All Trainer.fit attempts failed
2025-04-18 15:42:17,132 - INFO - Successfully imported Trainer, TrainerArgs, load_tts_samples, setup_model from TTS.bin.train_tts
2025-04-18 15:42:22,467 - INFO - Found config for Zhongli: voice_datasets\Zhongli\zhongli_config.json
2025-04-18 15:42:22,467 - INFO - Found 1 character configs in voice_datasets
2025-04-18 15:42:22,468 - INFO - Loaded configuration from voice_datasets\Zhongli\zhongli_config.json
2025-04-18 15:42:22,468 - INFO - Training model for Zhongli...
2025-04-18 15:42:22,469 - INFO - Loaded configuration from voice_datasets\Zhongli\zhongli_config.json
2025-04-18 15:42:22,469 - INFO - Model tts_models/en/ek1/tacotron2 not found in cache. Attempting to download.
2025-04-18 15:42:22,489 - INFO - Successfully downloaded model: tts_models/en/ek1/tacotron2 to C:\Users\DRAGOHN/.cache/tts/tts_models--en--ek1--tacotron2
2025-04-18 15:42:22,490 - INFO - Using CPU for training.
2025-04-18 15:42:22,492 - INFO - Using training metadata file at: voice_datasets\Zhongli\metadata.csv
2025-04-18 15:42:22,492 - INFO - Using validation metadata file at: voice_datasets\Zhongli\valid.csv
2025-04-18 15:42:22,492 - INFO - Using Trainer.fit with dataset preprocessing from TTS.bin.train_tts
2025-04-18 15:42:22,495 - WARNING - Trainer.fit with preprocessing failed: 'dict' object has no attribute 'meta_file_attn_mask'
Traceback (most recent call last):
  File "D:\Scripts\EchoPersona\train_tts_model.py", line 312, in train_model
    train_samples, eval_samples = load_tts_samples(
                                  ^^^^^^^^^^^^^^^^^
  File "D:\Scripts\EchoPersona\.venv\Lib\site-packages\TTS\tts\datasets\__init__.py", line 137, in load_tts_samples
    if dataset.meta_file_attn_mask:
       ^^^^^^^^^^^^^^^^^^^^^^^^^^^
AttributeError: 'dict' object has no attribute 'meta_file_attn_mask'

2025-04-18 15:42:22,495 - INFO - Attempting manual dataset handling with Trainer.fit
2025-04-18 15:42:30,151 - ERROR - Manual dataset handling failed: 'Coqpit' object has no attribute 'output_path'
Traceback (most recent call last):
  File "D:\Scripts\EchoPersona\train_tts_model.py", line 312, in train_model
    train_samples, eval_samples = load_tts_samples(
                                  ^^^^^^^^^^^^^^^^^
  File "D:\Scripts\EchoPersona\.venv\Lib\site-packages\TTS\tts\datasets\__init__.py", line 137, in load_tts_samples
    if dataset.meta_file_attn_mask:
       ^^^^^^^^^^^^^^^^^^^^^^^^^^^
AttributeError: 'dict' object has no attribute 'meta_file_attn_mask'

During handling of the above exception, another exception occurred:

Traceback (most recent call last):
  File "D:\Scripts\EchoPersona\train_tts_model.py", line 359, in train_model
    trainer = Trainer(
              ^^^^^^^^
  File "D:\Scripts\EchoPersona\.venv\Lib\site-packages\trainer\trainer.py", line 414, in __init__
    output_path = get_experiment_folder_path(config.output_path, config.run_name)
                                             ^^^^^^^^^^^^^^^^^^
  File "D:\Scripts\EchoPersona\.venv\Lib\site-packages\coqpit\coqpit.py", line 626, in __getattribute__
    value = super().__getattribute__(arg)
            ^^^^^^^^^^^^^^^^^^^^^^^^^^^^^
AttributeError: 'Coqpit' object has no attribute 'output_path'

2025-04-18 15:42:30,153 - ERROR - Training failed: All Trainer.fit attempts failed
Traceback (most recent call last):
  File "D:\Scripts\EchoPersona\train_tts_model.py", line 312, in train_model
    train_samples, eval_samples = load_tts_samples(
                                  ^^^^^^^^^^^^^^^^^
  File "D:\Scripts\EchoPersona\.venv\Lib\site-packages\TTS\tts\datasets\__init__.py", line 137, in load_tts_samples
    if dataset.meta_file_attn_mask:
       ^^^^^^^^^^^^^^^^^^^^^^^^^^^
AttributeError: 'dict' object has no attribute 'meta_file_attn_mask'

During handling of the above exception, another exception occurred:

Traceback (most recent call last):
  File "D:\Scripts\EchoPersona\train_tts_model.py", line 359, in train_model
    trainer = Trainer(
              ^^^^^^^^
  File "D:\Scripts\EchoPersona\.venv\Lib\site-packages\trainer\trainer.py", line 414, in __init__
    output_path = get_experiment_folder_path(config.output_path, config.run_name)
                                             ^^^^^^^^^^^^^^^^^^
  File "D:\Scripts\EchoPersona\.venv\Lib\site-packages\coqpit\coqpit.py", line 626, in __getattribute__
    value = super().__getattribute__(arg)
            ^^^^^^^^^^^^^^^^^^^^^^^^^^^^^
AttributeError: 'Coqpit' object has no attribute 'output_path'

During handling of the above exception, another exception occurred:

Traceback (most recent call last):
  File "D:\Scripts\EchoPersona\train_tts_model.py", line 378, in train_model
    raise RuntimeError("All Trainer.fit attempts failed")
RuntimeError: All Trainer.fit attempts failed

2025-04-18 15:42:30,154 - ERROR - Failed to process Zhongli: All Trainer.fit attempts failed
2025-04-18 15:46:35,548 - INFO - Successfully imported Trainer, TrainerArgs, load_tts_samples, setup_model from TTS.bin.train_tts
2025-04-18 15:46:40,777 - INFO - Found config for Zhongli: voice_datasets\Zhongli\zhongli_config.json
2025-04-18 15:46:40,777 - INFO - Found 1 character configs in voice_datasets
2025-04-18 15:46:40,778 - INFO - Loaded configuration from voice_datasets\Zhongli\zhongli_config.json
2025-04-18 15:46:40,778 - INFO - Training model for Zhongli...
2025-04-18 15:46:40,779 - INFO - Loaded configuration from voice_datasets\Zhongli\zhongli_config.json
2025-04-18 15:46:40,786 - INFO - Model tts_models/en/ek1/tacotron2 not found in cache. Attempting to download.
2025-04-18 15:46:40,798 - INFO - Successfully downloaded model: tts_models/en/ek1/tacotron2 to C:\Users\DRAGOHN/.cache/tts/tts_models--en--ek1--tacotron2
2025-04-18 15:46:40,798 - INFO - Using CPU for training.
2025-04-18 15:46:40,801 - INFO - Using training metadata file at: voice_datasets\Zhongli\metadata.csv
2025-04-18 15:46:40,801 - INFO - Using validation metadata file at: voice_datasets\Zhongli\valid.csv
2025-04-18 15:46:40,801 - INFO - Using Trainer.fit with dataset preprocessing from TTS.bin.train_tts
2025-04-18 15:46:40,803 - WARNING - Trainer.fit with preprocessing failed: 'dict' object has no attribute 'meta_file_attn_mask'
Traceback (most recent call last):
  File "D:\Scripts\EchoPersona\train_tts_model.py", line 317, in train_model
    train_samples, eval_samples = load_tts_samples(
                                  ^^^^^^^^^^^^^^^^^
  File "D:\Scripts\EchoPersona\.venv\Lib\site-packages\TTS\tts\datasets\__init__.py", line 137, in load_tts_samples
    if dataset.meta_file_attn_mask:
       ^^^^^^^^^^^^^^^^^^^^^^^^^^^
AttributeError: 'dict' object has no attribute 'meta_file_attn_mask'

2025-04-18 15:46:40,803 - INFO - Attempting manual dataset handling with Trainer.fit
2025-04-18 15:46:40,956 - ERROR - Manual dataset handling failed: 'Coqpit' object has no attribute 'output_path'
Traceback (most recent call last):
  File "D:\Scripts\EchoPersona\train_tts_model.py", line 317, in train_model
    train_samples, eval_samples = load_tts_samples(
                                  ^^^^^^^^^^^^^^^^^
  File "D:\Scripts\EchoPersona\.venv\Lib\site-packages\TTS\tts\datasets\__init__.py", line 137, in load_tts_samples
    if dataset.meta_file_attn_mask:
       ^^^^^^^^^^^^^^^^^^^^^^^^^^^
AttributeError: 'dict' object has no attribute 'meta_file_attn_mask'

During handling of the above exception, another exception occurred:

Traceback (most recent call last):
  File "D:\Scripts\EchoPersona\train_tts_model.py", line 364, in train_model
    trainer = Trainer(
              ^^^^^^^^
  File "D:\Scripts\EchoPersona\.venv\Lib\site-packages\trainer\trainer.py", line 414, in __init__
    output_path = get_experiment_folder_path(config.output_path, config.run_name)
                                             ^^^^^^^^^^^^^^^^^^
  File "D:\Scripts\EchoPersona\.venv\Lib\site-packages\coqpit\coqpit.py", line 626, in __getattribute__
    value = super().__getattribute__(arg)
            ^^^^^^^^^^^^^^^^^^^^^^^^^^^^^
AttributeError: 'Coqpit' object has no attribute 'output_path'

2025-04-18 15:46:40,959 - ERROR - Training failed: All Trainer.fit attempts failed
Traceback (most recent call last):
  File "D:\Scripts\EchoPersona\train_tts_model.py", line 317, in train_model
    train_samples, eval_samples = load_tts_samples(
                                  ^^^^^^^^^^^^^^^^^
  File "D:\Scripts\EchoPersona\.venv\Lib\site-packages\TTS\tts\datasets\__init__.py", line 137, in load_tts_samples
    if dataset.meta_file_attn_mask:
       ^^^^^^^^^^^^^^^^^^^^^^^^^^^
AttributeError: 'dict' object has no attribute 'meta_file_attn_mask'

During handling of the above exception, another exception occurred:

Traceback (most recent call last):
  File "D:\Scripts\EchoPersona\train_tts_model.py", line 364, in train_model
    trainer = Trainer(
              ^^^^^^^^
  File "D:\Scripts\EchoPersona\.venv\Lib\site-packages\trainer\trainer.py", line 414, in __init__
    output_path = get_experiment_folder_path(config.output_path, config.run_name)
                                             ^^^^^^^^^^^^^^^^^^
  File "D:\Scripts\EchoPersona\.venv\Lib\site-packages\coqpit\coqpit.py", line 626, in __getattribute__
    value = super().__getattribute__(arg)
            ^^^^^^^^^^^^^^^^^^^^^^^^^^^^^
AttributeError: 'Coqpit' object has no attribute 'output_path'

During handling of the above exception, another exception occurred:

Traceback (most recent call last):
  File "D:\Scripts\EchoPersona\train_tts_model.py", line 383, in train_model
    raise RuntimeError("All Trainer.fit attempts failed")
RuntimeError: All Trainer.fit attempts failed

2025-04-18 15:46:40,960 - ERROR - Failed to process Zhongli: All Trainer.fit attempts failed
