2025-04-18 13:05:47,422 - INFO - Successfully imported Trainer, TrainerArgs, load_tts_samples, setup_model from TTS.bin.train_tts
2025-04-18 13:05:52,490 - INFO - Found config for Hu Tao: voice_datasets\Hu Tao\Hu Tao_config.json
2025-04-18 13:05:52,491 - INFO - Found config for Xiao: voice_datasets\Xiao\Xiao_config.json
2025-04-18 13:05:52,491 - INFO - Found 2 character configs in voice_datasets
2025-04-18 13:32:44,235 - INFO - Successfully imported Trainer, TrainerArgs, load_tts_samples, setup_model from TTS.bin.train_tts
2025-04-18 13:32:49,206 - INFO - Found config for Hu Tao: voice_datasets\Hu Tao\Hu Tao_config.json
2025-04-18 13:32:49,207 - INFO - Found config for Xiao: voice_datasets\Xiao\Xiao_config.json
2025-04-18 13:32:49,208 - INFO - Found 2 character configs in voice_datasets
2025-04-18 13:33:03,295 - INFO - Loaded configuration from voice_datasets\Hu Tao\Hu Tao_config.json
2025-04-18 13:33:03,298 - INFO - Loaded configuration from voice_datasets\Hu Tao\Hu Tao_config.json
2025-04-18 13:33:03,298 - INFO - Model tts_models/en/ek1/tacotron2 not found in cache. Attempting to download.
2025-04-18 13:33:03,310 - INFO - Successfully downloaded model: tts_models/en/ek1/tacotron2 to C:\Users\DRAGOHN/.cache/tts/tts_models--en--ek1--tacotron2
2025-04-18 13:33:03,310 - INFO - Using CPU for training.
2025-04-18 13:33:03,311 - INFO - Checking training metadata file at: voice_datasets\Hu Tao\wavs\metadata.csv
2025-04-18 13:33:03,311 - INFO - Checking validation metadata file at: voice_datasets\Hu Tao\wavs\valid.csv
2025-04-18 13:33:03,312 - ERROR - Training failed: Training metadata file not found: voice_datasets\Hu Tao\wavs\metadata.csv
Traceback (most recent call last):
  File "D:\Scripts\EchoPersona\train_tts_model.py", line 253, in train_model
    raise FileNotFoundError(
FileNotFoundError: Training metadata file not found: voice_datasets\Hu Tao\wavs\metadata.csv

2025-04-18 13:34:53,659 - INFO - Successfully imported Trainer, TrainerArgs, load_tts_samples, setup_model from TTS.bin.train_tts
2025-04-18 13:34:59,175 - INFO - Found config for Hu Tao: voice_datasets\Hu Tao\Hu Tao_config.json
2025-04-18 13:34:59,177 - INFO - Found config for Xiao: voice_datasets\Xiao\Xiao_config.json
2025-04-18 13:34:59,178 - INFO - Found 2 character configs in voice_datasets
2025-04-18 13:35:03,536 - INFO - Loaded configuration from voice_datasets\Hu Tao\Hu Tao_config.json
2025-04-18 13:35:03,539 - INFO - Loaded configuration from voice_datasets\Hu Tao\Hu Tao_config.json
2025-04-18 13:35:03,539 - INFO - Model tts_models/en/ek1/tacotron2 not found in cache. Attempting to download.
2025-04-18 13:35:03,553 - INFO - Successfully downloaded model: tts_models/en/ek1/tacotron2 to C:\Users\DRAGOHN/.cache/tts/tts_models--en--ek1--tacotron2
2025-04-18 13:35:03,553 - INFO - Using CPU for training.
2025-04-18 13:35:03,554 - INFO - Checking training metadata file at: D:\Scripts\EchoPersona\voice_datasets\Hu Tao\wavs\metadata.csv
2025-04-18 13:35:03,555 - INFO - Checking validation metadata file at: D:\Scripts\EchoPersona\voice_datasets\Hu Tao\wavs\valid.csv
2025-04-18 13:35:03,555 - ERROR - Training failed: Training metadata file not found: D:\Scripts\EchoPersona\voice_datasets\Hu Tao\wavs\metadata.csv
Traceback (most recent call last):
  File "D:\Scripts\EchoPersona\train_tts_model.py", line 254, in train_model
    raise FileNotFoundError(
FileNotFoundError: Training metadata file not found: D:\Scripts\EchoPersona\voice_datasets\Hu Tao\wavs\metadata.csv

2025-04-18 13:36:56,910 - INFO - Successfully imported Trainer, TrainerArgs, load_tts_samples, setup_model from TTS.bin.train_tts
2025-04-18 13:37:01,917 - INFO - Found config for Hu Tao: voice_datasets\Hu Tao\Hu Tao_config.json
2025-04-18 13:37:01,918 - INFO - Found config for Xiao: voice_datasets\Xiao\Xiao_config.json
2025-04-18 13:37:01,918 - INFO - Found 2 character configs in voice_datasets
2025-04-18 13:37:35,255 - INFO - Loaded configuration from voice_datasets\Hu Tao\Hu Tao_config.json
2025-04-18 13:37:35,260 - INFO - Loaded configuration from voice_datasets\Hu Tao\Hu Tao_config.json
2025-04-18 13:37:35,261 - INFO - Model tts_models/en/ek1/tacotron2 not found in cache. Attempting to download.
2025-04-18 13:37:35,274 - INFO - Successfully downloaded model: tts_models/en/ek1/tacotron2 to C:\Users\DRAGOHN/.cache/tts/tts_models--en--ek1--tacotron2
2025-04-18 13:37:35,274 - INFO - Using CPU for training.
2025-04-18 13:37:35,276 - INFO - Checking training metadata file at: D:\Scripts\EchoPersona\voice_datasets\Hu Tao\wavs\metadata.csv
2025-04-18 13:37:35,277 - INFO - Checking validation metadata file at: D:\Scripts\EchoPersona\voice_datasets\Hu Tao\wavs\valid.csv
2025-04-18 13:37:35,277 - ERROR - Training failed: Training metadata file not found: D:\Scripts\EchoPersona\voice_datasets\Hu Tao\wavs\metadata.csv
Traceback (most recent call last):
  File "D:\Scripts\EchoPersona\train_tts_model.py", line 254, in train_model
    raise FileNotFoundError(
FileNotFoundError: Training metadata file not found: D:\Scripts\EchoPersona\voice_datasets\Hu Tao\wavs\metadata.csv

2025-04-18 13:54:45,814 - INFO - Successfully imported Trainer, TrainerArgs, load_tts_samples, setup_model from TTS.bin.train_tts
2025-04-18 13:54:50,866 - INFO - Found config for Zhongli: voice_datasets\Zhongli\Zhongli_config.json
2025-04-18 13:54:50,866 - INFO - Found 1 character configs in voice_datasets
2025-04-18 13:54:57,666 - INFO - Loaded configuration from voice_datasets\Zhongli\Zhongli_config.json
2025-04-18 13:54:57,670 - INFO - Loaded configuration from voice_datasets\Zhongli\Zhongli_config.json
2025-04-18 13:54:57,670 - INFO - Model tts_models/en/ek1/tacotron2 not found in cache. Attempting to download.
2025-04-18 13:54:57,682 - INFO - Successfully downloaded model: tts_models/en/ek1/tacotron2 to C:\Users\DRAGOHN/.cache/tts/tts_models--en--ek1--tacotron2
2025-04-18 13:54:57,683 - INFO - Using CPU for training.
2025-04-18 13:54:57,684 - INFO - Checking training metadata file at: D:\Scripts\EchoPersona\voice_datasets\Zhongli\wavs\metadata.csv
2025-04-18 13:54:57,684 - INFO - Checking validation metadata file at: D:\Scripts\EchoPersona\voice_datasets\Zhongli\wavs\valid.csv
2025-04-18 13:54:57,686 - ERROR - Training failed: Training metadata file not found: D:\Scripts\EchoPersona\voice_datasets\Zhongli\wavs\metadata.csv
Traceback (most recent call last):
  File "D:\Scripts\EchoPersona\train_tts_model.py", line 254, in train_model
    raise FileNotFoundError(
FileNotFoundError: Training metadata file not found: D:\Scripts\EchoPersona\voice_datasets\Zhongli\wavs\metadata.csv

2025-04-18 13:55:10,084 - INFO - Loaded configuration from voice_datasets\Zhongli\Zhongli_config.json
2025-04-18 13:55:10,084 - ERROR - Required path does not exist: voice_datasets\Zhongli\metadata.csv
2025-04-18 13:55:10,084 - ERROR - Failed to load configuration from voice_datasets\Zhongli\Zhongli_config.json: Invalid configuration: Missing or non-existent data paths.
2025-04-18 13:55:56,585 - INFO - Successfully imported Trainer, TrainerArgs, load_tts_samples, setup_model from TTS.bin.train_tts
2025-04-18 13:56:01,543 - INFO - Found config for Zhongli: voice_datasets\Zhongli\Zhongli_config.json
2025-04-18 13:56:01,543 - INFO - Found 1 character configs in voice_datasets
2025-04-18 13:56:08,065 - INFO - Loaded configuration from voice_datasets\Zhongli\Zhongli_config.json
2025-04-18 13:56:08,067 - INFO - Loaded configuration from voice_datasets\Zhongli\Zhongli_config.json
2025-04-18 13:56:08,068 - INFO - Model tts_models/en/ek1/tacotron2 not found in cache. Attempting to download.
2025-04-18 13:56:08,079 - INFO - Successfully downloaded model: tts_models/en/ek1/tacotron2 to C:\Users\DRAGOHN/.cache/tts/tts_models--en--ek1--tacotron2
2025-04-18 13:56:08,080 - INFO - Using CPU for training.
2025-04-18 13:56:08,081 - INFO - Checking training metadata file at: D:\Scripts\EchoPersona\voice_datasets\Zhongli\wavs\metadata.csv
2025-04-18 13:56:08,081 - INFO - Checking validation metadata file at: D:\Scripts\EchoPersona\voice_datasets\Zhongli\wavs\valid.csv
2025-04-18 13:56:08,081 - ERROR - Training failed: Validation metadata file not found: D:\Scripts\EchoPersona\voice_datasets\Zhongli\wavs\valid.csv
Traceback (most recent call last):
  File "D:\Scripts\EchoPersona\train_tts_model.py", line 258, in train_model
    raise FileNotFoundError(
FileNotFoundError: Validation metadata file not found: D:\Scripts\EchoPersona\voice_datasets\Zhongli\wavs\valid.csv

2025-04-18 13:56:25,477 - INFO - Loaded configuration from voice_datasets\Zhongli\Zhongli_config.json
2025-04-18 13:56:25,479 - INFO - Loaded configuration from voice_datasets\Zhongli\Zhongli_config.json
2025-04-18 13:56:25,480 - INFO - Model tts_models/en/ek1/tacotron2 not found in cache. Attempting to download.
2025-04-18 13:56:25,487 - INFO - Successfully downloaded model: tts_models/en/ek1/tacotron2 to C:\Users\DRAGOHN/.cache/tts/tts_models--en--ek1--tacotron2
2025-04-18 13:56:25,487 - INFO - Using CPU for training.
2025-04-18 13:56:25,488 - INFO - Checking training metadata file at: D:\Scripts\EchoPersona\voice_datasets\Zhongli\wavs\metadata.csv
2025-04-18 13:56:25,488 - INFO - Checking validation metadata file at: D:\Scripts\EchoPersona\voice_datasets\Zhongli\wavs\valid.csv
2025-04-18 13:56:25,489 - INFO - Using Trainer.fit with dataset preprocessing from TTS.bin.train_tts
2025-04-18 13:56:25,491 - WARNING - Trainer.fit with preprocessing failed: 'dict' object has no attribute 'meta_file_attn_mask'
Traceback (most recent call last):
  File "D:\Scripts\EchoPersona\train_tts_model.py", line 269, in train_model
    train_samples, eval_samples = load_tts_samples(
                                  ^^^^^^^^^^^^^^^^^
  File "D:\Scripts\EchoPersona\.venv\Lib\site-packages\TTS\tts\datasets\__init__.py", line 137, in load_tts_samples
    if dataset.meta_file_attn_mask:
       ^^^^^^^^^^^^^^^^^^^^^^^^^^^
AttributeError: 'dict' object has no attribute 'meta_file_attn_mask'

2025-04-18 13:56:25,491 - INFO - Attempting manual dataset handling with Trainer.fit
2025-04-18 13:56:25,493 - INFO - Loaded configuration from voice_datasets\Zhongli\Zhongli_config.json
2025-04-18 13:56:25,496 - ERROR - Manual dataset handling failed: 'dict' object has no attribute 'parse_known_args'
Traceback (most recent call last):
  File "D:\Scripts\EchoPersona\train_tts_model.py", line 269, in train_model
    train_samples, eval_samples = load_tts_samples(
                                  ^^^^^^^^^^^^^^^^^
  File "D:\Scripts\EchoPersona\.venv\Lib\site-packages\TTS\tts\datasets\__init__.py", line 137, in load_tts_samples
    if dataset.meta_file_attn_mask:
       ^^^^^^^^^^^^^^^^^^^^^^^^^^^
AttributeError: 'dict' object has no attribute 'meta_file_attn_mask'

During handling of the above exception, another exception occurred:

Traceback (most recent call last):
  File "D:\Scripts\EchoPersona\train_tts_model.py", line 324, in train_model
    trainer = Trainer(
              ^^^^^^^^
  File "D:\Scripts\EchoPersona\.venv\Lib\site-packages\trainer\trainer.py", line 400, in __init__
    config, new_fields = self.init_training(args, coqpit_overrides, config)
                         ^^^^^^^^^^^^^^^^^^^^^^^^^^^^^^^^^^^^^^^^^^^^^^^^^^
  File "D:\Scripts\EchoPersona\.venv\Lib\site-packages\trainer\trainer.py", line 745, in init_training
    config.parse_known_args(coqpit_overrides, relaxed_parser=True)
    ^^^^^^^^^^^^^^^^^^^^^^^
AttributeError: 'dict' object has no attribute 'parse_known_args'

2025-04-18 13:56:25,499 - ERROR - Training failed: All Trainer.fit attempts failed
Traceback (most recent call last):
  File "D:\Scripts\EchoPersona\train_tts_model.py", line 269, in train_model
    train_samples, eval_samples = load_tts_samples(
                                  ^^^^^^^^^^^^^^^^^
  File "D:\Scripts\EchoPersona\.venv\Lib\site-packages\TTS\tts\datasets\__init__.py", line 137, in load_tts_samples
    if dataset.meta_file_attn_mask:
       ^^^^^^^^^^^^^^^^^^^^^^^^^^^
AttributeError: 'dict' object has no attribute 'meta_file_attn_mask'

During handling of the above exception, another exception occurred:

Traceback (most recent call last):
  File "D:\Scripts\EchoPersona\train_tts_model.py", line 324, in train_model
    trainer = Trainer(
              ^^^^^^^^
  File "D:\Scripts\EchoPersona\.venv\Lib\site-packages\trainer\trainer.py", line 400, in __init__
    config, new_fields = self.init_training(args, coqpit_overrides, config)
                         ^^^^^^^^^^^^^^^^^^^^^^^^^^^^^^^^^^^^^^^^^^^^^^^^^^
  File "D:\Scripts\EchoPersona\.venv\Lib\site-packages\trainer\trainer.py", line 745, in init_training
    config.parse_known_args(coqpit_overrides, relaxed_parser=True)
    ^^^^^^^^^^^^^^^^^^^^^^^
AttributeError: 'dict' object has no attribute 'parse_known_args'

During handling of the above exception, another exception occurred:

Traceback (most recent call last):
  File "D:\Scripts\EchoPersona\train_tts_model.py", line 343, in train_model
    raise RuntimeError("All Trainer.fit attempts failed")
RuntimeError: All Trainer.fit attempts failed

2025-04-18 14:35:37,237 - INFO - Successfully imported Trainer, TrainerArgs, load_tts_samples, setup_model from TTS.bin.train_tts
2025-04-18 14:35:42,315 - INFO - Found config for Zhongli: voice_datasets\Zhongli\zhongli_config.json
2025-04-18 14:35:42,316 - INFO - Found 1 character configs in voice_datasets
2025-04-18 14:35:51,907 - INFO - Loaded configuration from voice_datasets\Zhongli\zhongli_config.json
2025-04-18 14:35:51,908 - INFO - Loaded configuration from voice_datasets\Zhongli\zhongli_config.json
2025-04-18 14:35:51,910 - INFO - Model tts_models/en/ek1/tacotron2 not found in cache. Attempting to download.
2025-04-18 14:35:51,921 - INFO - Successfully downloaded model: tts_models/en/ek1/tacotron2 to C:\Users\DRAGOHN/.cache/tts/tts_models--en--ek1--tacotron2
2025-04-18 14:35:51,922 - INFO - Using CPU for training.
2025-04-18 14:35:51,924 - INFO - Using training metadata file at: voice_datasets\Zhongli\metadata.csv
2025-04-18 14:35:51,924 - INFO - Using validation metadata file at: voice_datasets\Zhongli\valid.csv
2025-04-18 14:35:51,924 - INFO - Using Trainer.fit with dataset preprocessing from TTS.bin.train_tts
2025-04-18 14:35:51,925 - WARNING - Trainer.fit with preprocessing failed: [Errno 2] No such file or directory: 'voice_datasets\\Zhongli\\wavs\\metadata.csv'
Traceback (most recent call last):
  File "D:\Scripts\EchoPersona\train_tts_model.py", line 280, in train_model
    train_samples, eval_samples = load_tts_samples(
                                  ^^^^^^^^^^^^^^^^^
  File "D:\Scripts\EchoPersona\.venv\Lib\site-packages\TTS\tts\datasets\__init__.py", line 120, in load_tts_samples
    meta_data_train = formatter(root_path, meta_file_train, ignored_speakers=ignored_speakers)
                      ^^^^^^^^^^^^^^^^^^^^^^^^^^^^^^^^^^^^^^^^^^^^^^^^^^^^^^^^^^^^^^^^^^^^^^^^
  File "D:\Scripts\EchoPersona\.venv\Lib\site-packages\TTS\tts\datasets\formatters.py", line 197, in ljspeech
    with open(txt_file, "r", encoding="utf-8") as ttf:
         ^^^^^^^^^^^^^^^^^^^^^^^^^^^^^^^^^^^^^
FileNotFoundError: [Errno 2] No such file or directory: 'voice_datasets\\Zhongli\\wavs\\metadata.csv'

2025-04-18 14:35:51,926 - INFO - Attempting manual dataset handling with Trainer.fit
2025-04-18 14:35:51,926 - INFO - Loaded configuration from voice_datasets\Zhongli\zhongli_config.json
2025-04-18 14:35:51,930 - ERROR - Manual dataset handling failed: 'dict' object has no attribute 'parse_known_args'
Traceback (most recent call last):
  File "D:\Scripts\EchoPersona\train_tts_model.py", line 280, in train_model
    train_samples, eval_samples = load_tts_samples(
                                  ^^^^^^^^^^^^^^^^^
  File "D:\Scripts\EchoPersona\.venv\Lib\site-packages\TTS\tts\datasets\__init__.py", line 120, in load_tts_samples
    meta_data_train = formatter(root_path, meta_file_train, ignored_speakers=ignored_speakers)
                      ^^^^^^^^^^^^^^^^^^^^^^^^^^^^^^^^^^^^^^^^^^^^^^^^^^^^^^^^^^^^^^^^^^^^^^^^
  File "D:\Scripts\EchoPersona\.venv\Lib\site-packages\TTS\tts\datasets\formatters.py", line 197, in ljspeech
    with open(txt_file, "r", encoding="utf-8") as ttf:
         ^^^^^^^^^^^^^^^^^^^^^^^^^^^^^^^^^^^^^
FileNotFoundError: [Errno 2] No such file or directory: 'voice_datasets\\Zhongli\\wavs\\metadata.csv'

During handling of the above exception, another exception occurred:

Traceback (most recent call last):
  File "D:\Scripts\EchoPersona\train_tts_model.py", line 335, in train_model
    trainer = Trainer(
              ^^^^^^^^
  File "D:\Scripts\EchoPersona\.venv\Lib\site-packages\trainer\trainer.py", line 400, in __init__
    config, new_fields = self.init_training(args, coqpit_overrides, config)
                         ^^^^^^^^^^^^^^^^^^^^^^^^^^^^^^^^^^^^^^^^^^^^^^^^^^
  File "D:\Scripts\EchoPersona\.venv\Lib\site-packages\trainer\trainer.py", line 745, in init_training
    config.parse_known_args(coqpit_overrides, relaxed_parser=True)
    ^^^^^^^^^^^^^^^^^^^^^^^
AttributeError: 'dict' object has no attribute 'parse_known_args'

2025-04-18 14:35:51,933 - ERROR - Training failed: All Trainer.fit attempts failed
Traceback (most recent call last):
  File "D:\Scripts\EchoPersona\train_tts_model.py", line 280, in train_model
    train_samples, eval_samples = load_tts_samples(
                                  ^^^^^^^^^^^^^^^^^
  File "D:\Scripts\EchoPersona\.venv\Lib\site-packages\TTS\tts\datasets\__init__.py", line 120, in load_tts_samples
    meta_data_train = formatter(root_path, meta_file_train, ignored_speakers=ignored_speakers)
                      ^^^^^^^^^^^^^^^^^^^^^^^^^^^^^^^^^^^^^^^^^^^^^^^^^^^^^^^^^^^^^^^^^^^^^^^^
  File "D:\Scripts\EchoPersona\.venv\Lib\site-packages\TTS\tts\datasets\formatters.py", line 197, in ljspeech
    with open(txt_file, "r", encoding="utf-8") as ttf:
         ^^^^^^^^^^^^^^^^^^^^^^^^^^^^^^^^^^^^^
FileNotFoundError: [Errno 2] No such file or directory: 'voice_datasets\\Zhongli\\wavs\\metadata.csv'

During handling of the above exception, another exception occurred:

Traceback (most recent call last):
  File "D:\Scripts\EchoPersona\train_tts_model.py", line 335, in train_model
    trainer = Trainer(
              ^^^^^^^^
  File "D:\Scripts\EchoPersona\.venv\Lib\site-packages\trainer\trainer.py", line 400, in __init__
    config, new_fields = self.init_training(args, coqpit_overrides, config)
                         ^^^^^^^^^^^^^^^^^^^^^^^^^^^^^^^^^^^^^^^^^^^^^^^^^^
  File "D:\Scripts\EchoPersona\.venv\Lib\site-packages\trainer\trainer.py", line 745, in init_training
    config.parse_known_args(coqpit_overrides, relaxed_parser=True)
    ^^^^^^^^^^^^^^^^^^^^^^^
AttributeError: 'dict' object has no attribute 'parse_known_args'

During handling of the above exception, another exception occurred:

Traceback (most recent call last):
  File "D:\Scripts\EchoPersona\train_tts_model.py", line 354, in train_model
    raise RuntimeError("All Trainer.fit attempts failed")
RuntimeError: All Trainer.fit attempts failed

2025-04-18 14:44:07,508 - INFO - Successfully imported Trainer, TrainerArgs, load_tts_samples, setup_model from TTS.bin.train_tts
2025-04-18 14:44:13,235 - INFO - Found config for Zhongli: voice_datasets\Zhongli\zhongli_config.json
2025-04-18 14:44:13,235 - INFO - Found 1 character configs in voice_datasets
2025-04-18 14:44:19,153 - INFO - Loaded configuration from voice_datasets\Zhongli\zhongli_config.json
2025-04-18 14:44:19,155 - INFO - Loaded configuration from voice_datasets\Zhongli\zhongli_config.json
2025-04-18 14:44:19,156 - INFO - Model tts_models/en/ek1/tacotron2 not found in cache. Attempting to download.
2025-04-18 14:44:19,168 - INFO - Successfully downloaded model: tts_models/en/ek1/tacotron2 to C:\Users\DRAGOHN/.cache/tts/tts_models--en--ek1--tacotron2
2025-04-18 14:44:19,169 - INFO - Using CPU for training.
2025-04-18 14:44:19,170 - ERROR - Training failed: Metadata files not found in expected locations: voice_datasets\Zhongli\voice_datasets\Zhongli\metadata.csv, voice_datasets\Zhongli\voice_datasets\Zhongli\valid.csv
Traceback (most recent call last):
  File "D:\Scripts\EchoPersona\train_tts_model.py", line 271, in train_model
    meta_file_train_path, meta_file_val_path = adjust_metadata_paths(dataset_path, meta_file_train, meta_file_val)
                                               ^^^^^^^^^^^^^^^^^^^^^^^^^^^^^^^^^^^^^^^^^^^^^^^^^^^^^^^^^^^^^^^^^^^
  File "D:\Scripts\EchoPersona\train_tts_model.py", line 214, in adjust_metadata_paths
    raise FileNotFoundError(
FileNotFoundError: Metadata files not found in expected locations: voice_datasets\Zhongli\voice_datasets\Zhongli\metadata.csv, voice_datasets\Zhongli\voice_datasets\Zhongli\valid.csv

2025-04-18 14:46:08,734 - INFO - Successfully imported Trainer, TrainerArgs, load_tts_samples, setup_model from TTS.bin.train_tts
2025-04-18 14:46:13,674 - INFO - Found config for Zhongli: voice_datasets\Zhongli\zhongli_config.json
2025-04-18 14:46:13,674 - INFO - Found 1 character configs in voice_datasets
2025-04-18 14:46:21,304 - INFO - Loaded configuration from voice_datasets\Zhongli\zhongli_config.json
2025-04-18 14:46:21,305 - INFO - Loaded configuration from voice_datasets\Zhongli\zhongli_config.json
2025-04-18 14:46:21,306 - INFO - Model tts_models/en/ek1/tacotron2 not found in cache. Attempting to download.
2025-04-18 14:46:21,319 - INFO - Successfully downloaded model: tts_models/en/ek1/tacotron2 to C:\Users\DRAGOHN/.cache/tts/tts_models--en--ek1--tacotron2
2025-04-18 14:46:21,320 - INFO - Using CPU for training.
2025-04-18 14:46:21,321 - INFO - Using training metadata file at: voice_datasets\Zhongli\metadata.csv
2025-04-18 14:46:21,322 - INFO - Using validation metadata file at: voice_datasets\Zhongli\valid.csv
2025-04-18 14:46:21,322 - ERROR - Training failed: Coqpit.__init__() got an unexpected keyword argument 'output_path'
Traceback (most recent call last):
  File "D:\Scripts\EchoPersona\train_tts_model.py", line 282, in train_model
    config = Coqpit(**config)
             ^^^^^^^^^^^^^^^^
TypeError: Coqpit.__init__() got an unexpected keyword argument 'output_path'

